<?xml version="1.0" ?>
<!-- =================================================================================== -->
<!-- |    This document was autogenerated by xacro from ur5_joint_limited_box_robot_robotiq3.urdf.xacro | -->
<!-- |    EDITING THIS FILE BY HAND IS NOT RECOMMENDED                                 | -->
<!-- =================================================================================== -->
<robot name="ur5" xmlns:xacro="http://ros.org/wiki/xacro">
  <gazebo>
    <plugin filename="libgazebo_ros_control.so" name="ros_control">
      <!--robotNamespace>/</robotNamespace-->
      <!--robotSimType>gazebo_ros_control/DefaultRobotHWSim</robotSimType-->
    </plugin>
    <!--
    <plugin name="gazebo_ros_power_monitor_controller" filename="libgazebo_ros_power_monitor.so">
      <alwaysOn>true</alwaysOn>
      <updateRate>1.0</updateRate>
      <timeout>5</timeout>
      <powerStateTopic>power_state</powerStateTopic>
      <powerStateRate>10.0</powerStateRate>
      <fullChargeCapacity>87.78</fullChargeCapacity>     
      <dischargeRate>-474</dischargeRate>
      <chargeRate>525</chargeRate>
      <dischargeVoltage>15.52</dischargeVoltage>
      <chargeVoltage>16.41</chargeVoltage>
    </plugin>
-->
  </gazebo>
  <!-- measured from model -->
  <!--property name="shoulder_height" value="0.089159" /-->
  <!--property name="shoulder_offset" value="0.13585" /-->
  <!-- shoulder_offset - elbow_offset + wrist_1_length = 0.10915 -->
  <!--property name="upper_arm_length" value="0.42500" /-->
  <!--property name="elbow_offset" value="0.1197" /-->
  <!-- CAD measured -->
  <!--property name="forearm_length" value="0.39225" /-->
  <!--property name="wrist_1_length" value="0.093" /-->
  <!-- CAD measured -->
  <!--property name="wrist_2_length" value="0.09465" /-->
  <!-- In CAD this distance is 0.930, but in the spec it is 0.09465 -->
  <!--property name="wrist_3_length" value="0.0823" /-->
  <!-- manually measured -->
  <link name="base_link">
    <visual>
      <geometry>
        <mesh filename="package://ur_description/meshes/ur5/visual/base.dae"/>
      </geometry>
      <material name="LightGrey">
        <color rgba="0.7 0.7 0.7 1.0"/>
      </material>
    </visual>
    <collision>
      <geometry>
        <mesh filename="package://ur_description/meshes/ur5/collision/base.stl"/>
      </geometry>
    </collision>
    <inertial>
      <mass value="4.0"/>
      <origin rpy="0 0 0" xyz="0.0 0.0 0.0"/>
      <inertia ixx="0.00443333156" ixy="0.0" ixz="0.0" iyy="0.00443333156" iyz="0.0" izz="0.0072"/>
    </inertial>
  </link>
  <joint name="shoulder_pan_joint" type="revolute">
    <parent link="base_link"/>
    <child link="shoulder_link"/>
    <origin rpy="0.0 0.0 0.0" xyz="0.0 0.0 0.089159"/>
    <axis xyz="0 0 1"/>
    <limit effort="150.0" lower="-3.14159265" upper="3.14159265" velocity="3.15"/>
    <dynamics damping="0.0" friction="0.0"/>
  </joint>
  <link name="shoulder_link">
    <visual>
      <geometry>
        <mesh filename="package://ur_description/meshes/ur5/visual/shoulder.dae"/>
      </geometry>
      <material name="LightGrey">
        <color rgba="0.7 0.7 0.7 1.0"/>
      </material>
    </visual>
    <collision>
      <geometry>
        <mesh filename="package://ur_description/meshes/ur5/collision/shoulder.stl"/>
      </geometry>
    </collision>
    <inertial>
      <mass value="3.7"/>
      <origin rpy="0 0 0" xyz="0.0 0.0 0.0"/>
      <inertia ixx="0.010267495893" ixy="0.0" ixz="0.0" iyy="0.010267495893" iyz="0.0" izz="0.00666"/>
    </inertial>
  </link>
  <joint name="shoulder_lift_joint" type="revolute">
    <parent link="shoulder_link"/>
    <child link="upper_arm_link"/>
    <origin rpy="0.0 1.570796325 0.0" xyz="0.0 0.13585 0.0"/>
    <axis xyz="0 1 0"/>
    <limit effort="150.0" lower="-3.14159265" upper="-0.9" velocity="3.15"/>
    <!-- <limit effort="150.0" lower="-3.14159265" upper="-0.8" velocity="3.15"/> -->
    <dynamics damping="0.0" friction="0.0"/>
  </joint>
  <link name="upper_arm_link">
    <visual>
      <geometry>
        <mesh filename="package://ur_description/meshes/ur5/visual/upperarm.dae"/>
      </geometry>
      <material name="LightGrey">
        <color rgba="0.7 0.7 0.7 1.0"/>
      </material>
    </visual>
    <collision>
      <geometry>
        <mesh filename="package://ur_description/meshes/ur5/collision/upperarm.stl"/>
      </geometry>
    </collision>
    <inertial>
      <mass value="8.393"/>
      <origin rpy="0 0 0" xyz="0.0 0.0 0.28"/>
      <inertia ixx="0.22689067591" ixy="0.0" ixz="0.0" iyy="0.22689067591" iyz="0.0" izz="0.0151074"/>
    </inertial>
  </link>
  <joint name="elbow_joint" type="revolute">
    <parent link="upper_arm_link"/>
    <child link="forearm_link"/>
    <origin rpy="0.0 0.0 0.0" xyz="0.0 -0.1197 0.425"/>
    <axis xyz="0 1 0"/>
    <limit effort="150.0" lower="-3.14159265" upper="3.14159265" velocity="3.15"/>
    <dynamics damping="0.0" friction="0.0"/>
  </joint>
  <link name="forearm_link">
    <visual>
      <geometry>
        <mesh filename="package://ur_description/meshes/ur5/visual/forearm.dae"/>
      </geometry>
      <material name="LightGrey">
        <color rgba="0.7 0.7 0.7 1.0"/>
      </material>
    </visual>
    <collision>
      <geometry>
        <mesh filename="package://ur_description/meshes/ur5/collision/forearm.stl"/>
      </geometry>
    </collision>
    <inertial>
      <mass value="2.275"/>
      <origin rpy="0 0 0" xyz="0.0 0.0 0.25"/>
      <inertia ixx="0.049443313556" ixy="0.0" ixz="0.0" iyy="0.049443313556" iyz="0.0" izz="0.004095"/>
    </inertial>
  </link>
  <joint name="wrist_1_joint" type="revolute">
    <parent link="forearm_link"/>
    <child link="wrist_1_link"/>
    <origin rpy="0.0 1.570796325 0.0" xyz="0.0 0.0 0.39225"/>
    <axis xyz="0 1 0"/>
    <limit effort="28.0" lower="-3.14159265" upper="3.14159265" velocity="3.2"/>
    <dynamics damping="0.0" friction="0.0"/>
  </joint>
  <link name="wrist_1_link">
    <visual>
      <geometry>
        <mesh filename="package://ur_description/meshes/ur5/visual/wrist1.dae"/>
      </geometry>
      <material name="LightGrey">
        <color rgba="0.7 0.7 0.7 1.0"/>
      </material>
    </visual>
    <collision>
      <geometry>
        <mesh filename="package://ur_description/meshes/ur5/collision/wrist1.stl"/>
      </geometry>
    </collision>
    <inertial>
      <mass value="1.219"/>
      <origin rpy="0 0 0" xyz="0.0 0.0 0.0"/>
      <inertia ixx="0.111172755531" ixy="0.0" ixz="0.0" iyy="0.111172755531" iyz="0.0" izz="0.21942"/>
    </inertial>
  </link>
  <joint name="wrist_2_joint" type="revolute">
    <parent link="wrist_1_link"/>
    <child link="wrist_2_link"/>
    <origin rpy="0.0 0.0 0.0" xyz="0.0 0.093 0.0"/>
    <axis xyz="0 0 1"/>
    <limit effort="28.0" lower="-3.14159265" upper="3.14159265" velocity="3.2"/>
    <dynamics damping="0.0" friction="0.0"/>
  </joint>
  <link name="wrist_2_link">
    <visual>
      <geometry>
        <mesh filename="package://ur_description/meshes/ur5/visual/wrist2.dae"/>
      </geometry>
      <material name="LightGrey">
        <color rgba="0.7 0.7 0.7 1.0"/>
      </material>
    </visual>
    <collision>
      <geometry>
        <mesh filename="package://ur_description/meshes/ur5/collision/wrist2.stl"/>
      </geometry>
    </collision>
    <inertial>
      <mass value="1.219"/>
      <origin rpy="0 0 0" xyz="0.0 0.0 0.0"/>
      <inertia ixx="0.111172755531" ixy="0.0" ixz="0.0" iyy="0.111172755531" iyz="0.0" izz="0.21942"/>
    </inertial>
  </link>
  <joint name="wrist_3_joint" type="revolute">
    <parent link="wrist_2_link"/>
    <child link="wrist_3_link"/>
    <origin rpy="0.0 0.0 0.0" xyz="0.0 0.0 0.09465"/>
    <axis xyz="0 1 0"/>
    <limit effort="28.0" lower="-3.14159265" upper="3.14159265" velocity="3.2"/>
    <dynamics damping="0.0" friction="0.0"/>
  </joint>
  <link name="wrist_3_link">
    <visual>
      <geometry>
        <mesh filename="package://ur_description/meshes/ur5/visual/wrist3.dae"/>
      </geometry>
      <material name="LightGrey">
        <color rgba="0.7 0.7 0.7 1.0"/>
      </material>
    </visual>
    <collision>
      <geometry>
        <mesh filename="package://ur_description/meshes/ur5/collision/wrist3.stl"/>
      </geometry>
    </collision>
    <inertial>
      <mass value="0.1879"/>
      <origin rpy="0 0 0" xyz="0.0 0.0 0.0"/>
      <inertia ixx="0.0171364731454" ixy="0.0" ixz="0.0" iyy="0.0171364731454" iyz="0.0" izz="0.033822"/>
    </inertial>
  </link>
  <joint name="ee_fixed_joint" type="fixed">
    <parent link="wrist_3_link"/>
    <child link="ee_link"/>
    <origin rpy="0.0 0.0 1.570796325" xyz="0.0 0.0823 0.0"/>
  </joint>
  <link name="ee_link">
    <collision>
      <geometry>
        <box size="0.01 0.01 0.01"/>
      </geometry>
      <origin rpy="0 0 0" xyz="-0.01 0 0"/>
    </collision>
  </link>
  <transmission name="shoulder_pan_trans">
    <type>transmission_interface/SimpleTransmission</type>
    <joint name="shoulder_pan_joint">
      <hardwareInterface>PositionJointInterface</hardwareInterface>
    </joint>
    <actuator name="shoulder_pan_motor">
      <mechanicalReduction>1</mechanicalReduction>
    </actuator>
  </transmission>
  <transmission name="shoulder_lift_trans">
    <type>transmission_interface/SimpleTransmission</type>
    <joint name="shoulder_lift_joint">
      <hardwareInterface>PositionJointInterface</hardwareInterface>
    </joint>
    <actuator name="shoulder_lift_motor">
      <mechanicalReduction>1</mechanicalReduction>
    </actuator>
  </transmission>
  <transmission name="elbow_trans">
    <type>transmission_interface/SimpleTransmission</type>
    <joint name="elbow_joint">
      <hardwareInterface>PositionJointInterface</hardwareInterface>
    </joint>
    <actuator name="elbow_motor">
      <mechanicalReduction>1</mechanicalReduction>
    </actuator>
  </transmission>
  <transmission name="wrist_1_trans">
    <type>transmission_interface/SimpleTransmission</type>
    <joint name="wrist_1_joint">
      <hardwareInterface>PositionJointInterface</hardwareInterface>
    </joint>
    <actuator name="wrist_1_motor">
      <mechanicalReduction>1</mechanicalReduction>
    </actuator>
  </transmission>
  <transmission name="wrist_2_trans">
    <type>transmission_interface/SimpleTransmission</type>
    <joint name="wrist_2_joint">
      <hardwareInterface>PositionJointInterface</hardwareInterface>
    </joint>
    <actuator name="wrist_2_motor">
      <mechanicalReduction>1</mechanicalReduction>
    </actuator>
  </transmission>
  <transmission name="wrist_3_trans">
    <type>transmission_interface/SimpleTransmission</type>
    <joint name="wrist_3_joint">
      <hardwareInterface>PositionJointInterface</hardwareInterface>
    </joint>
    <actuator name="wrist_3_motor">
      <mechanicalReduction>1</mechanicalReduction>
    </actuator>
  </transmission>
  <!-- nothing to do here at the moment -->
  <!-- ROS base_link to UR 'Base' Coordinates transform -->
  <link name="base"/>
  <joint name="base_link-base_fixed_joint" type="fixed">
    <!-- NOTE: this rotation is only needed as long as base_link itself is
                 not corrected wrt the real robot (ie: rotated over 180
                 degrees)
      -->
    <origin rpy="0 0 -3.14159265" xyz="0 0 0"/>
    <parent link="base_link"/>
    <child link="base"/>
  </joint>
  <!-- Frame coincident with all-zeros TCP on UR controller -->
  <link name="tool0"/>
  <joint name="wrist_3_link-tool0_fixed_joint" type="fixed">
    <origin rpy="-1.570796325 0 0" xyz="0 0.0823 0"/>
    <parent link="wrist_3_link"/>
    <child link="tool0"/>
  </joint>
  <link name="world"/>
  <!-- box -->
  <link name="box_link">
    <visual>
      <geometry>
        <box size=".6 .4 0.87"/>
      </geometry>
    </visual>
  </link>
  <!-- attach the box to the world-->
  <joint name="world_joint" type="fixed">
    <parent link="world"/>
    <child link="box_link"/>
    <origin rpy="0.0 0.0 0.0" xyz="0.0 0 0.435"/>
  </joint>
  <!-- attach the robot to the box -->
  <joint name="box_joint" type="fixed">
    <parent link="box_link"/>
    <child link="base_link"/>
    <origin rpy="0.0 0.0 0.0" xyz="0.0 0.0 0.435"/>
  </joint>
  <!-- joint attaching parent link to robotiq hand -->
  <joint name="gripperrobotiq_hand_joint" type="fixed">
    <origin rpy="1.570796325 0 0" xyz="0 0 0.0423"/>
    <parent link="tool0"/>
    <child link="gripperpalm"/>
  </joint>
  <!-- Link list -->
  <!-- Link 0 -->
  <link name="gripperfinger_1_link_0">
    <visual>
      <origin rpy="0 0 0" xyz="0 0 0"/>
      <geometry>
        <mesh filename="package://robotiq_s_model_visualization/meshes/s-model_articulated/visual/link_0.STL"/>
      </geometry>
      <material name="green">
        <color rgba="0 1 0 1"/>
      </material>
    </visual>
    <collision>
      <origin rpy="0 0 0" xyz="0 0 0"/>
      <geometry>
        <mesh filename="package://robotiq_s_model_visualization/meshes/s-model_articulated/collision/link_0.STL"/>
      </geometry>
      <material name="yellow">
        <color rgba="0 1 1 1"/>
      </material>
    </collision>
    <inertial>
      <mass value="0.1"/>
      <origin xyz="-0.01 0 0"/>
      <inertia ixx="0.000018" ixy="0" ixz="0" iyy="0.000025" iyz="0" izz="0.000025"/>
    </inertial>
  </link>
  <gazebo reference="gripperfinger_1_link_0">
    <mu1>1.1</mu1>
    <mu2>1.1</mu2>
  </gazebo>
  <!-- Link 1 -->
  <link name="gripperfinger_1_link_1">
    <visual>
      <origin rpy="0 0 1.5708" xyz="0 0.05717 0"/>
      <geometry>
        <mesh filename="package://robotiq_s_model_visualization/meshes/s-model_articulated/visual/link_1.STL"/>
      </geometry>
      <material name="green"/>
    </visual>
    <collision>
      <origin rpy="0 0 1.5708" xyz="0 0.05717 0"/>
      <geometry>
        <mesh filename="package://robotiq_s_model_visualization/meshes/s-model_articulated/collision/link_1.STL"/>
      </geometry>
      <material name="yellow">
        <color rgba="0 1 1 1"/>
      </material>
    </collision>
    <inertial>
      <origin rpy="0 0 1.5708" xyz="0.00053 0.03218 0"/>
      <mass value="0.047"/>
      <inertia ixx="0.00000499332" ixy="0.00000091312" ixz="-0.00000000120" iyy="0.00006434531" iyz="-0.00000000007" izz="0.00006061917"/>
    </inertial>
  </link>
  <gazebo reference="gripperfinger_1_link_1">
    <mu1>1.1</mu1>
    <mu2>1.1</mu2>
  </gazebo>
  <!-- Link 2 -->
  <link name="gripperfinger_1_link_2">
    <visual>
      <origin rpy="0 0 1.5708" xyz="0 0.03810 0.0075"/>
      <geometry>
        <mesh filename="package://robotiq_s_model_visualization/meshes/s-model_articulated/visual/link_2.STL"/>
      </geometry>
      <material name="green"/>
    </visual>
    <collision>
      <origin rpy="0 0 1.5708" xyz="0 0.03810 0.0075"/>
      <geometry>
        <mesh filename="package://robotiq_s_model_visualization/meshes/s-model_articulated/collision/link_2.STL"/>
      </geometry>
      <material name="yellow"/>
    </collision>
    <inertial>
      <origin rpy="0 0 1.5708" xyz="0.00048 0.02167 0.00018"/>
      <mass value="0.03284"/>
      <inertia ixx="0.00000348008" ixy="0.00000031940" ixz="0.00000013041" iyy="0.00002248123" iyz="0.00000000291" izz="0.00001986346"/>
    </inertial>
  </link>
  <gazebo reference="gripperfinger_1_link_2">
    <mu1>1.1</mu1>
    <mu2>1.1</mu2>
  </gazebo>
  <!-- Link 3 -->
  <link name="gripperfinger_1_link_3">
    <visual>
      <origin rpy="0 0 0" xyz="0 0 0"/>
      <geometry>
        <mesh filename="package://robotiq_s_model_visualization/meshes/s-model_articulated/visual/link_3.STL"/>
      </geometry>
      <material name="green"/>
    </visual>
    <collision>
      <origin rpy="0 0 0" xyz="0 0 0"/>
      <geometry>
        <mesh filename="package://robotiq_s_model_visualization/meshes/s-model_articulated/collision/link_3.STL"/>
      </geometry>
      <material name="yellow"/>
    </collision>
    <inertial>
      <origin rpy="0 0 0" xyz="0.01626 0.00049 0.0002"/>
      <mass value="0.03354"/>
      <inertia ixx="0.00000305151" ixy="0.00000089792" ixz="0.00000000249" iyy="0.00001427978" iyz="-0.00000001191" izz="0.00001264126"/>
    </inertial>
  </link>
  <gazebo reference="gripperfinger_1_link_3">
    <mu1>1.1</mu1>
    <mu2>1.1</mu2>
  </gazebo>
  <!-- Link proximal actuating hinge -->
  <link name="gripperfinger_1_link_proximal_actuating_hinge">
    <visual>
      <origin rpy="0 0 0" xyz="0.01429 0 0"/>
      <geometry>
        <box size="0.02858 .0075 .002"/>
      </geometry>
    </visual>
    <collision>
      <origin rpy="0 0 0" xyz="0.01429 0 0"/>
      <geometry>
        <box size="0.02858 .0075 .002"/>
      </geometry>
    </collision>
    <inertial>
      <origin rpy="0 0 0" xyz="0.0012 -0.00162 -0.00161"/>
      <mass value="0.02647"/>
      <inertia ixx="0.00000156447" ixy="0.000000236226" ixz="-0.00000014862" iyy="0.00000221068" iyz="-0.00000014369" izz="0.00000323175"/>
    </inertial>
  </link>
  <gazebo reference="gripperfinger_1_link_proximal_actuating_hinge">
    <mu1>1.1</mu1>
    <mu2>1.1</mu2>
  </gazebo>
  <!-- Link paraproximal actuating hinge -->
  <link name="gripperfinger_1_link_paraproximal_actuating_hinge">
    <visual>
      <origin rpy="0 0 0" xyz="0.01143 0 0"/>
      <geometry>
        <box size="0.02286 .0075 .002"/>
      </geometry>
    </visual>
    <collision>
      <origin rpy="0 0 0" xyz="0.01143 0 0"/>
      <geometry>
        <box size="0.02286 .0075 .002"/>
      </geometry>
    </collision>
    <inertial>
      <origin rpy="0 0 0" xyz="0.0064 0 0"/>
      <!-- copied from proximal_actuating_hinge -->
      <mass value="0.00362"/>
      <inertia ixx="0.00000012043" ixy="0" ixz="0" iyy="0.00000053588" iyz="0" izz="0.00000065322"/>
    </inertial>
  </link>
  <gazebo reference="gripperfinger_1_link_paraproximal_actuating_hinge">
    <mu1>1.1</mu1>
    <mu2>1.1</mu2>
  </gazebo>
  <!-- Link proximal actuating bar -->
  <link name="gripperfinger_1_link_proximal_actuating_bar">
    <visual>
      <origin rpy="0 0 0" xyz="0.026789 0 0"/>
      <geometry>
        <box size="0.05398 .0075 .002"/>
      </geometry>
    </visual>
    <collision>
      <origin rpy="0 0 0" xyz="0.026789 0 0"/>
      <geometry>
        <box size="0.05398 .0075 .002"/>
      </geometry>
    </collision>
    <inertial>
      <origin rpy="0 0 0" xyz="0.02699 -0.00122 0"/>
      <mass value="0.00659"/>
      <inertia ixx="0.00000008348" ixy="-0.0000002179" ixz="0.00000000134" iyy="0.00000719076" iyz="0" izz="0.00000718272"/>
    </inertial>
  </link>
  <gazebo reference="gripperfinger_1_link_proximal_actuating_bar">
    <mu1>1.1</mu1>
    <mu2>1.1</mu2>
  </gazebo>
  <!-- Link paraproximal bar -->
  <link name="gripperfinger_1_link_paraproximal_bar">
    <visual>
      <origin rpy="0 0 0" xyz="0.02885 0 0"/>
      <geometry>
        <box size="0.05770 .0075 .002"/>
      </geometry>
    </visual>
    <collision>
      <origin rpy="0 0 0" xyz="0.02885 0 0"/>
      <geometry>
        <box size="0.05770 .0075 .002"/>
      </geometry>
    </collision>
    <inertial>
      <origin rpy="0 0 0" xyz="0.02858 -0.00129 0"/>
      <mass value="0.00732"/>
      <inertia ixx="0.00000009065" ixy="-0.00000027047" ixz="0.00000000142" iyy="0.00000878034" iyz="0" izz="0.00000877558"/>
    </inertial>
  </link>
  <gazebo reference="gripperfinger_1_link_paraproximal_bar">
    <mu1>1.1</mu1>
    <mu2>1.1</mu2>
  </gazebo>
  <!-- Link median actuating hinge -->
  <link name="gripperfinger_1_link_median_actuating_hinge">
    <visual>
      <origin rpy="0 0 0" xyz="0 0 0"/>
      <geometry>
        <box size=".02 .02 .002"/>
      </geometry>
    </visual>
    <collision>
      <origin rpy="0 0 0" xyz="0 0 0"/>
      <geometry>
        <box size=".02 .02 .002"/>
      </geometry>
    </collision>
    <inertial>
      <origin rpy="0 0 0" xyz="0.0092 0.00514 0"/>
      <mass value="0.00359"/>
      <inertia ixx="0.00000024735" ixy="0.00000023619" ixz="0" iyy="0.00000047681" iyz="0" izz="0.00000071813"/>
    </inertial>
  </link>
  <gazebo reference="gripperfinger_1_link_median_actuating_hinge">
    <mu1>1.1</mu1>
    <mu2>1.1</mu2>
  </gazebo>
  <!-- Link median bar -->
  <link name="gripperfinger_1_link_median_bar">
    <visual>
      <origin rpy="0 0 0" xyz="0.01905 0 0"/>
      <geometry>
        <box size="0.0381 .0075 .002"/>
      </geometry>
    </visual>
    <collision>
      <origin rpy="0 0 0" xyz="0.01905 0 0"/>
      <geometry>
        <box size="0.0381 .0075 .002"/>
      </geometry>
    </collision>
    <inertial>
      <origin rpy="0 0 0" xyz="0.01905 -0.00107 0"/>
      <mass value="0.00538"/>
      <inertia ixx="0.00000006639" ixy="-0.00000010996" ixz="0.00000000094" iyy="0.00000305318" iyz="0" izz="0.00000304657"/>
    </inertial>
  </link>
  <gazebo reference="gripperfinger_1_link_median_bar">
    <mu1>1.1</mu1>
    <mu2>1.1</mu2>
  </gazebo>
  <!-- Link paramedian hinge -->
  <link name="gripperfinger_1_link_paramedian_hinge">
    <visual>
      <origin rpy="0 0 0" xyz="0 0 0"/>
      <geometry>
        <box size=".02 .02 .002"/>
      </geometry>
    </visual>
    <collision>
      <origin rpy="0 0 0" xyz="0 0 0"/>
      <geometry>
        <box size=".02 .02 .002"/>
      </geometry>
    </collision>
    <inertial>
      <origin rpy="0 0 0" xyz="-0.01025 0.00046 0"/>
      <mass value="0.00276"/>
      <inertia ixx="0.00000004213" ixy="-0.00000001491" ixz="0" iyy="0.00000050258" iyz="0" izz="0.00000054007"/>
    </inertial>
  </link>
  <gazebo reference="gripperfinger_1_link_paramedian_hinge">
    <mu1>1.1</mu1>
    <mu2>1.1</mu2>
  </gazebo>
  <!-- Link median bar underactuated -->
  <link name="gripperfinger_1_link_median_bar_underactuated">
    <visual>
      <origin rpy="0 0 0" xyz="0.01905 0 0"/>
      <geometry>
        <box size="0.0381 .0075 .002"/>
      </geometry>
    </visual>
    <collision>
      <origin rpy="0 0 0" xyz="0.01905 0 0"/>
      <geometry>
        <box size="0.0381 .0075 .002"/>
      </geometry>
    </collision>
    <inertial>
      <origin rpy="0 0 0" xyz="0.01905 -0.00107 0"/>
      <mass value="0.00538"/>
      <inertia ixx="0.00000006639" ixy="-0.00000010996" ixz="-0.00000000094" iyy="0.00000305318" iyz="0" izz="0.00000304657"/>
    </inertial>
  </link>
  <gazebo reference="gripperfinger_1_link_median_bar_underactuated">
    <mu1>1.1</mu1>
    <mu2>1.1</mu2>
  </gazebo>
  <!-- Link paradistal hinge -->
  <link name="gripperfinger_1_link_paradistal_hinge">
    <visual>
      <origin rpy="0 0 0" xyz="0 0 0"/>
      <geometry>
        <box size=".02 .02 .002"/>
      </geometry>
    </visual>
    <collision>
      <origin rpy="0 0 0" xyz="0 0 0"/>
      <geometry>
        <box size=".02 0.02 .002"/>
      </geometry>
    </collision>
    <inertial>
      <origin rpy="0 0 0" xyz="0.00548 0 0"/>
      <mass value="0.00158"/>
      <inertia ixx="0.00000001907" ixy="0" ixz="0" iyy="0.00000010970" iyz="0" izz="0.00000012610"/>
    </inertial>
  </link>
  <gazebo reference="gripperfinger_1_link_paradistal_hinge">
    <mu1>1.1</mu1>
    <mu2>1.1</mu2>
  </gazebo>
  <!-- End of link list -->
  <!-- Joint list -->
  <!-- Joint proximal actuating hinge -->
  <joint name="gripperfinger_1_joint_proximal_actuating_hinge" type="revolute">
    <parent link="gripperfinger_1_link_0"/>
    <child link="gripperfinger_1_link_proximal_actuating_hinge"/>
    <axis xyz="0 0 1"/>
    <origin rpy="0 0 -2.0906" xyz="0 0 0.01"/>
    <limit effort="100" lower="-3.1416" upper="3.1416" velocity="100"/>
  </joint>
  <gazebo reference="gripperfinger_1_joint_proximal_actuating_hinge">
    <implicitSpringDamper>1</implicitSpringDamper>
  </gazebo>
  <!-- Joint paraproximal actuating hinge -->
  <joint name="gripperfinger_1_joint_paraproximal_actuating_hinge" type="revolute">
    <parent link="gripperfinger_1_link_0"/>
    <child link="gripperfinger_1_link_paraproximal_actuating_hinge"/>
    <axis xyz="0 0 1"/>
    <origin rpy="0 0 -2.0906" xyz="0 0 -0.01"/>
    <limit effort="100" lower="-3.1416" upper="3.1416" velocity="100"/>
  </joint>
  <gazebo reference="gripperfinger_1_joint_paraproximal_actuating_hinge">
    <implicitSpringDamper>1</implicitSpringDamper>
  </gazebo>
  <!-- Joint proximal actuating bar -->
  <joint name="gripperfinger_1_joint_proximal_actuating_bar" type="revolute">
    <parent link="gripperfinger_1_link_proximal_actuating_hinge"/>
    <child link="gripperfinger_1_link_proximal_actuating_bar"/>
    <axis xyz="0 0 1"/>
    <origin rpy="0 0 1.8616" xyz="0.02858 0 0"/>
    <limit effort="100" lower="-3.1416" upper="3.1416" velocity="100"/>
  </joint>
  <gazebo reference="gripperfinger_1_joint_proximal_actuating_bar">
    <implicitSpringDamper>1</implicitSpringDamper>
  </gazebo>
  <!-- Joint paraproximal bar -->
  <joint name="gripperfinger_1_joint_paraproximal_bar" type="revolute">
    <parent link="gripperfinger_1_link_paraproximal_actuating_hinge"/>
    <child link="gripperfinger_1_link_paraproximal_bar"/>
    <axis xyz="0 0 1"/>
    <origin rpy="0 0 1.57" xyz="0.02286 0 0"/>
    <limit effort="100" lower="-3.1416" upper="3.1416" velocity="100"/>
  </joint>
  <gazebo reference="gripperfinger_1_joint_paraproximal_bar">
    <implicitSpringDamper>1</implicitSpringDamper>
  </gazebo>
  <!-- Joint median actuating hinge -->
  <joint name="gripperfinger_1_joint_median_actuating_hinge" type="revolute">
    <parent link="gripperfinger_1_link_1"/>
    <child link="gripperfinger_1_link_median_actuating_hinge"/>
    <axis xyz="0 0 1"/>
    <origin rpy="0 0 -0.37" xyz="0 0.05715 0.01"/>
    <limit effort="100" lower="-3.1416" upper="3.1416" velocity="100"/>
  </joint>
  <gazebo reference="gripperfinger_1_joint_median_actuating_hinge">
    <implicitSpringDamper>1</implicitSpringDamper>
  </gazebo>
  <!-- Joint paramedian hinge -->
  <joint name="gripperfinger_1_joint_paramedian_hinge" type="revolute">
    <parent link="gripperfinger_1_link_1"/>
    <child link="gripperfinger_1_link_paramedian_hinge"/>
    <axis xyz="0 0 1"/>
    <!-- -0.37 is hand picked, 0.9719 is hand calculated from atan(0.02381/0.01625) -->
    <origin rpy="0 0 0" xyz="0 0.05715 -0.01"/>
    <limit effort="100" lower="-3.1416" upper="3.1416" velocity="100"/>
  </joint>
  <gazebo reference="gripperfinger_1_joint_paramedian_hinge">
    <implicitSpringDamper>1</implicitSpringDamper>
  </gazebo>
  <!-- Joint median actuating hinge median bar -->
  <joint name="gripperfinger_1_joint_median_actuating_hinge_median_bar" type="revolute">
    <parent link="gripperfinger_1_link_median_actuating_hinge"/>
    <child link="gripperfinger_1_link_median_bar"/>
    <axis xyz="0 0 1"/>
    <!-- hand calc 90 deg + atan(0.01516/0.01625) -->
    <origin rpy="0 0 2.3215" xyz="0.01625 0.01516 0"/>
    <limit effort="100" lower="-3.1416" upper="3.1416" velocity="100"/>
  </joint>
  <gazebo reference="gripperfinger_1_joint_median_actuating_hinge_median_bar">
    <implicitSpringDamper>1</implicitSpringDamper>
  </gazebo>
  <!-- Joint paradistal hinge -->
  <joint name="gripperfinger_1_joint_paradistal_hinge" type="revolute">
    <parent link="gripperfinger_1_link_2"/>
    <child link="gripperfinger_1_link_paradistal_hinge"/>
    <axis xyz="0 0 1"/>
    <origin rpy="0 0 0" xyz="0 0.039 -0.01"/>
    <limit effort="100" lower="-3.1416" upper="3.1416" velocity="100"/>
  </joint>
  <gazebo reference="gripperfinger_1_joint_paradistal_hinge">
    <implicitSpringDamper>1</implicitSpringDamper>
  </gazebo>
  <!-- Joint paramedian hinge median bar underactuated -->
  <joint name="gripperfinger_1_joint_paramedian_hinge_median_bar_underactuated" type="revolute">
    <parent link="gripperfinger_1_link_paramedian_hinge"/>
    <child link="gripperfinger_1_link_median_bar_underactuated"/>
    <axis xyz="0 0 1"/>
    <!-- hand calc 90 deg + atan(0.01227/0.00329) -->
    <origin rpy="0 0 1.5708" xyz="0.01227 0.00329 0"/>
    <limit effort="100" lower="-3.1416" upper="3.1416" velocity="100"/>
  </joint>
  <gazebo reference="gripperfinger_1_joint_paramedian_hinge_median_bar_underactuated">
    <implicitSpringDamper>1</implicitSpringDamper>
  </gazebo>
  <!-- Joint 1 -->
  <joint name="gripperfinger_1_joint_1" type="revolute">
    <origin rpy="0 0 -2.0906" xyz="0 0 0"/>
    <axis xyz="0 0 1"/>
    <parent link="gripperfinger_1_link_0"/>
    <child link="gripperfinger_1_link_1"/>
    <dynamics damping="1" friction="0"/>
    <!-- Limits: [0deg.,70deg.] -->
    <limit effort="60" lower="0" upper="1.2217" velocity="-1"/>
  </joint>
  <gazebo reference="gripperfinger_1_joint_1">
    <implicitSpringDamper>1</implicitSpringDamper>
  </gazebo>
  <!-- Joint 2 -->
  <joint name="gripperfinger_1_joint_2" type="revolute">
    <parent link="gripperfinger_1_link_1"/>
    <child link="gripperfinger_1_link_2"/>
    <dynamics damping="1" friction="0"/>
    <axis xyz="0 0 1"/>
    <origin rpy="0 0 0" xyz="0 0.05715 0"/>
    <!-- Limits: [0deg.,90deg.] -->
    <limit effort="60" lower="0" upper="1.5708" velocity="-1"/>
  </joint>
  <gazebo reference="gripperfinger_1_joint_2">
    <implicitSpringDamper>1</implicitSpringDamper>
  </gazebo>
  <!-- Joint 3 -->
  <joint name="gripperfinger_1_joint_3" type="revolute">
    <parent link="gripperfinger_1_link_2"/>
    <child link="gripperfinger_1_link_3"/>
    <dynamics damping="1" friction="0"/>
    <axis xyz="0 0 1"/>
    <origin rpy="0 0 2.0906" xyz="0 0.039 0"/>
    <!-- Limits: [-38deg.,60deg.] -->
    <limit effort="60" lower="-0.6632" upper="1.0471" velocity="-1"/>
  </joint>
  <gazebo reference="gripperfinger_1_joint_3">
    <implicitSpringDamper>1</implicitSpringDamper>
  </gazebo>
  <!-- end of joint list -->
  <!-- coupling joints in sdf -->
  <gazebo>
    <joint name="gripperfinger_1_link_proximal_actuating_bar_median_actuating_hinge_couple" type="revolute">
      <parent>gripperfinger_1_link_median_actuating_hinge</parent>
      <child>gripperfinger_1_link_proximal_actuating_bar</child>
      <pose>0.05398 0 0 0 0 0</pose>
      <axis>
        <dynamics>
          <damping>0</damping>
          <friction>0</friction>
        </dynamics>
        <xyz>0 0 1</xyz>
        <!-- <use_parent_model_frame>false</use_parent_model_frame> -->
      </axis>
    </joint>
  </gazebo>
  <gazebo reference="gripperfinger_1_link_proximal_actuating_bar_median_actuating_hinge_couple">
    <implicitSpringDamper>1</implicitSpringDamper>
  </gazebo>
  <gazebo>
    <joint name="gripperfinger_1_link_median_bar_link_3_couple" type="revolute">
      <parent>gripperfinger_1_link_3</parent>
      <child>gripperfinger_1_link_median_bar</child>
      <pose>0.0381 0 0 0 0 0</pose>
      <axis>
        <dynamics>
          <damping>0</damping>
          <friction>0</friction>
        </dynamics>
        <xyz>0 0 1</xyz>
        <!-- <use_parent_model_frame>false</use_parent_model_frame> -->
      </axis>
    </joint>
  </gazebo>
  <gazebo reference="gripperfinger_1_link_median_bar_link_3_couple">
    <implicitSpringDamper>1</implicitSpringDamper>
  </gazebo>
  <gazebo>
    <joint name="gripperfinger_1_link_paramedian_bar_paradistal_hinge_couple" type="revolute">
      <parent>gripperfinger_1_link_paradistal_hinge</parent>
      <child>gripperfinger_1_link_median_bar_underactuated</child>
      <pose>0.0381 0 0 0 0 0</pose>
      <axis>
        <dynamics>
          <damping>0</damping>
          <friction>0</friction>
        </dynamics>
        <xyz>0 0 1</xyz>
        <!-- <use_parent_model_frame>false</use_parent_model_frame> -->
      </axis>
    </joint>
  </gazebo>
  <gazebo reference="gripperfinger_1_link_median_bar_link_3_couple">
    <implicitSpringDamper>1</implicitSpringDamper>
  </gazebo>
  <gazebo>
    <joint name="gripperfinger_1_link_paradistal_hinge_link_3_couple" type="revolute">
      <parent>gripperfinger_1_link_paradistal_hinge</parent>
      <child>gripperfinger_1_link_3</child>
      <pose>0.0381 0 0 0 0 0</pose>
      <axis>
        <dynamics>
          <damping>0</damping>
          <friction>0</friction>
        </dynamics>
        <xyz>0 0 1</xyz>
        <!-- <use_parent_model_frame>false</use_parent_model_frame> -->
      </axis>
    </joint>
  </gazebo>
  <gazebo reference="gripperfinger_1_link_paradistal_hinge_link_3_couple">
    <implicitSpringDamper>1</implicitSpringDamper>
  </gazebo>
  <gazebo>
    <joint name="gripperfinger_1_link_paraproximal_bar_paramedian_hinge_couple" type="revolute">
      <parent>gripperfinger_1_link_paramedian_hinge</parent>
      <child>gripperfinger_1_link_paraproximal_bar</child>
      <pose>0.05770 0 0 0 0 0</pose>
      <axis>
        <dynamics>
          <damping>0</damping>
          <friction>0</friction>
        </dynamics>
        <xyz>0 0 1</xyz>
        <!-- <use_parent_model_frame>false</use_parent_model_frame> -->
      </axis>
    </joint>
  </gazebo>
  <gazebo reference="gripperfinger_1_link_paraproximal_bar_paramedian_hinge_couple">
    <implicitSpringDamper>1</implicitSpringDamper>
  </gazebo>
  <!-- Link list -->
  <!-- Link 0 -->
  <link name="gripperfinger_2_link_0">
    <visual>
      <origin rpy="0 0 0" xyz="0 0 0"/>
      <geometry>
        <mesh filename="package://robotiq_s_model_visualization/meshes/s-model_articulated/visual/link_0.STL"/>
      </geometry>
      <material name="green">
        <color rgba="0 1 0 1"/>
      </material>
    </visual>
    <collision>
      <origin rpy="0 0 0" xyz="0 0 0"/>
      <geometry>
        <mesh filename="package://robotiq_s_model_visualization/meshes/s-model_articulated/collision/link_0.STL"/>
      </geometry>
      <material name="yellow">
        <color rgba="0 1 1 1"/>
      </material>
    </collision>
    <inertial>
      <mass value="0.1"/>
      <origin xyz="-0.01 0 0"/>
      <inertia ixx="0.000018" ixy="0" ixz="0" iyy="0.000025" iyz="0" izz="0.000025"/>
    </inertial>
  </link>
  <gazebo reference="gripperfinger_2_link_0">
    <mu1>1.1</mu1>
    <mu2>1.1</mu2>
  </gazebo>
  <!-- Link 1 -->
  <link name="gripperfinger_2_link_1">
    <visual>
      <origin rpy="0 0 1.5708" xyz="0 0.05717 0"/>
      <geometry>
        <mesh filename="package://robotiq_s_model_visualization/meshes/s-model_articulated/visual/link_1.STL"/>
      </geometry>
      <material name="green"/>
    </visual>
    <collision>
      <origin rpy="0 0 1.5708" xyz="0 0.05717 0"/>
      <geometry>
        <mesh filename="package://robotiq_s_model_visualization/meshes/s-model_articulated/collision/link_1.STL"/>
      </geometry>
      <material name="yellow">
        <color rgba="0 1 1 1"/>
      </material>
    </collision>
    <inertial>
      <origin rpy="0 0 1.5708" xyz="0.00053 0.03218 0"/>
      <mass value="0.047"/>
      <inertia ixx="0.00000499332" ixy="0.00000091312" ixz="-0.00000000120" iyy="0.00006434531" iyz="-0.00000000007" izz="0.00006061917"/>
    </inertial>
  </link>
  <gazebo reference="gripperfinger_2_link_1">
    <mu1>1.1</mu1>
    <mu2>1.1</mu2>
  </gazebo>
  <!-- Link 2 -->
  <link name="gripperfinger_2_link_2">
    <visual>
      <origin rpy="0 0 1.5708" xyz="0 0.03810 0.0075"/>
      <geometry>
        <mesh filename="package://robotiq_s_model_visualization/meshes/s-model_articulated/visual/link_2.STL"/>
      </geometry>
      <material name="green"/>
    </visual>
    <collision>
      <origin rpy="0 0 1.5708" xyz="0 0.03810 0.0075"/>
      <geometry>
        <mesh filename="package://robotiq_s_model_visualization/meshes/s-model_articulated/collision/link_2.STL"/>
      </geometry>
      <material name="yellow"/>
    </collision>
    <inertial>
      <origin rpy="0 0 1.5708" xyz="0.00048 0.02167 0.00018"/>
      <mass value="0.03284"/>
      <inertia ixx="0.00000348008" ixy="0.00000031940" ixz="0.00000013041" iyy="0.00002248123" iyz="0.00000000291" izz="0.00001986346"/>
    </inertial>
  </link>
  <gazebo reference="gripperfinger_2_link_2">
    <mu1>1.1</mu1>
    <mu2>1.1</mu2>
  </gazebo>
  <!-- Link 3 -->
  <link name="gripperfinger_2_link_3">
    <visual>
      <origin rpy="0 0 0" xyz="0 0 0"/>
      <geometry>
        <mesh filename="package://robotiq_s_model_visualization/meshes/s-model_articulated/visual/link_3.STL"/>
      </geometry>
      <material name="green"/>
    </visual>
    <collision>
      <origin rpy="0 0 0" xyz="0 0 0"/>
      <geometry>
        <mesh filename="package://robotiq_s_model_visualization/meshes/s-model_articulated/collision/link_3.STL"/>
      </geometry>
      <material name="yellow"/>
    </collision>
    <inertial>
      <origin rpy="0 0 0" xyz="0.01626 0.00049 0.0002"/>
      <mass value="0.03354"/>
      <inertia ixx="0.00000305151" ixy="0.00000089792" ixz="0.00000000249" iyy="0.00001427978" iyz="-0.00000001191" izz="0.00001264126"/>
    </inertial>
  </link>
  <gazebo reference="gripperfinger_2_link_3">
    <mu1>1.1</mu1>
    <mu2>1.1</mu2>
  </gazebo>
  <!-- Link proximal actuating hinge -->
  <link name="gripperfinger_2_link_proximal_actuating_hinge">
    <visual>
      <origin rpy="0 0 0" xyz="0.01429 0 0"/>
      <geometry>
        <box size="0.02858 .0075 .002"/>
      </geometry>
    </visual>
    <collision>
      <origin rpy="0 0 0" xyz="0.01429 0 0"/>
      <geometry>
        <box size="0.02858 .0075 .002"/>
      </geometry>
    </collision>
    <inertial>
      <origin rpy="0 0 0" xyz="0.0012 -0.00162 -0.00161"/>
      <mass value="0.02647"/>
      <inertia ixx="0.00000156447" ixy="0.000000236226" ixz="-0.00000014862" iyy="0.00000221068" iyz="-0.00000014369" izz="0.00000323175"/>
    </inertial>
  </link>
  <gazebo reference="gripperfinger_2_link_proximal_actuating_hinge">
    <mu1>1.1</mu1>
    <mu2>1.1</mu2>
  </gazebo>
  <!-- Link paraproximal actuating hinge -->
  <link name="gripperfinger_2_link_paraproximal_actuating_hinge">
    <visual>
      <origin rpy="0 0 0" xyz="0.01143 0 0"/>
      <geometry>
        <box size="0.02286 .0075 .002"/>
      </geometry>
    </visual>
    <collision>
      <origin rpy="0 0 0" xyz="0.01143 0 0"/>
      <geometry>
        <box size="0.02286 .0075 .002"/>
      </geometry>
    </collision>
    <inertial>
      <origin rpy="0 0 0" xyz="0.0064 0 0"/>
      <!-- copied from proximal_actuating_hinge -->
      <mass value="0.00362"/>
      <inertia ixx="0.00000012043" ixy="0" ixz="0" iyy="0.00000053588" iyz="0" izz="0.00000065322"/>
    </inertial>
  </link>
  <gazebo reference="gripperfinger_2_link_paraproximal_actuating_hinge">
    <mu1>1.1</mu1>
    <mu2>1.1</mu2>
  </gazebo>
  <!-- Link proximal actuating bar -->
  <link name="gripperfinger_2_link_proximal_actuating_bar">
    <visual>
      <origin rpy="0 0 0" xyz="0.026789 0 0"/>
      <geometry>
        <box size="0.05398 .0075 .002"/>
      </geometry>
    </visual>
    <collision>
      <origin rpy="0 0 0" xyz="0.026789 0 0"/>
      <geometry>
        <box size="0.05398 .0075 .002"/>
      </geometry>
    </collision>
    <inertial>
      <origin rpy="0 0 0" xyz="0.02699 -0.00122 0"/>
      <mass value="0.00659"/>
      <inertia ixx="0.00000008348" ixy="-0.0000002179" ixz="0.00000000134" iyy="0.00000719076" iyz="0" izz="0.00000718272"/>
    </inertial>
  </link>
  <gazebo reference="gripperfinger_2_link_proximal_actuating_bar">
    <mu1>1.1</mu1>
    <mu2>1.1</mu2>
  </gazebo>
  <!-- Link paraproximal bar -->
  <link name="gripperfinger_2_link_paraproximal_bar">
    <visual>
      <origin rpy="0 0 0" xyz="0.02885 0 0"/>
      <geometry>
        <box size="0.05770 .0075 .002"/>
      </geometry>
    </visual>
    <collision>
      <origin rpy="0 0 0" xyz="0.02885 0 0"/>
      <geometry>
        <box size="0.05770 .0075 .002"/>
      </geometry>
    </collision>
    <inertial>
      <origin rpy="0 0 0" xyz="0.02858 -0.00129 0"/>
      <mass value="0.00732"/>
      <inertia ixx="0.00000009065" ixy="-0.00000027047" ixz="0.00000000142" iyy="0.00000878034" iyz="0" izz="0.00000877558"/>
    </inertial>
  </link>
  <gazebo reference="gripperfinger_2_link_paraproximal_bar">
    <mu1>1.1</mu1>
    <mu2>1.1</mu2>
  </gazebo>
  <!-- Link median actuating hinge -->
  <link name="gripperfinger_2_link_median_actuating_hinge">
    <visual>
      <origin rpy="0 0 0" xyz="0 0 0"/>
      <geometry>
        <box size=".02 .02 .002"/>
      </geometry>
    </visual>
    <collision>
      <origin rpy="0 0 0" xyz="0 0 0"/>
      <geometry>
        <box size=".02 .02 .002"/>
      </geometry>
    </collision>
    <inertial>
      <origin rpy="0 0 0" xyz="0.0092 0.00514 0"/>
      <mass value="0.00359"/>
      <inertia ixx="0.00000024735" ixy="0.00000023619" ixz="0" iyy="0.00000047681" iyz="0" izz="0.00000071813"/>
    </inertial>
  </link>
  <gazebo reference="gripperfinger_2_link_median_actuating_hinge">
    <mu1>1.1</mu1>
    <mu2>1.1</mu2>
  </gazebo>
  <!-- Link median bar -->
  <link name="gripperfinger_2_link_median_bar">
    <visual>
      <origin rpy="0 0 0" xyz="0.01905 0 0"/>
      <geometry>
        <box size="0.0381 .0075 .002"/>
      </geometry>
    </visual>
    <collision>
      <origin rpy="0 0 0" xyz="0.01905 0 0"/>
      <geometry>
        <box size="0.0381 .0075 .002"/>
      </geometry>
    </collision>
    <inertial>
      <origin rpy="0 0 0" xyz="0.01905 -0.00107 0"/>
      <mass value="0.00538"/>
      <inertia ixx="0.00000006639" ixy="-0.00000010996" ixz="0.00000000094" iyy="0.00000305318" iyz="0" izz="0.00000304657"/>
    </inertial>
  </link>
  <gazebo reference="gripperfinger_2_link_median_bar">
    <mu1>1.1</mu1>
    <mu2>1.1</mu2>
  </gazebo>
  <!-- Link paramedian hinge -->
  <link name="gripperfinger_2_link_paramedian_hinge">
    <visual>
      <origin rpy="0 0 0" xyz="0 0 0"/>
      <geometry>
        <box size=".02 .02 .002"/>
      </geometry>
    </visual>
    <collision>
      <origin rpy="0 0 0" xyz="0 0 0"/>
      <geometry>
        <box size=".02 .02 .002"/>
      </geometry>
    </collision>
    <inertial>
      <origin rpy="0 0 0" xyz="-0.01025 0.00046 0"/>
      <mass value="0.00276"/>
      <inertia ixx="0.00000004213" ixy="-0.00000001491" ixz="0" iyy="0.00000050258" iyz="0" izz="0.00000054007"/>
    </inertial>
  </link>
  <gazebo reference="gripperfinger_2_link_paramedian_hinge">
    <mu1>1.1</mu1>
    <mu2>1.1</mu2>
  </gazebo>
  <!-- Link median bar underactuated -->
  <link name="gripperfinger_2_link_median_bar_underactuated">
    <visual>
      <origin rpy="0 0 0" xyz="0.01905 0 0"/>
      <geometry>
        <box size="0.0381 .0075 .002"/>
      </geometry>
    </visual>
    <collision>
      <origin rpy="0 0 0" xyz="0.01905 0 0"/>
      <geometry>
        <box size="0.0381 .0075 .002"/>
      </geometry>
    </collision>
    <inertial>
      <origin rpy="0 0 0" xyz="0.01905 -0.00107 0"/>
      <mass value="0.00538"/>
      <inertia ixx="0.00000006639" ixy="-0.00000010996" ixz="-0.00000000094" iyy="0.00000305318" iyz="0" izz="0.00000304657"/>
    </inertial>
  </link>
  <gazebo reference="gripperfinger_2_link_median_bar_underactuated">
    <mu1>1.1</mu1>
    <mu2>1.1</mu2>
  </gazebo>
  <!-- Link paradistal hinge -->
  <link name="gripperfinger_2_link_paradistal_hinge">
    <visual>
      <origin rpy="0 0 0" xyz="0 0 0"/>
      <geometry>
        <box size=".02 .02 .002"/>
      </geometry>
    </visual>
    <collision>
      <origin rpy="0 0 0" xyz="0 0 0"/>
      <geometry>
        <box size=".02 0.02 .002"/>
      </geometry>
    </collision>
    <inertial>
      <origin rpy="0 0 0" xyz="0.00548 0 0"/>
      <mass value="0.00158"/>
      <inertia ixx="0.00000001907" ixy="0" ixz="0" iyy="0.00000010970" iyz="0" izz="0.00000012610"/>
    </inertial>
  </link>
  <gazebo reference="gripperfinger_2_link_paradistal_hinge">
    <mu1>1.1</mu1>
    <mu2>1.1</mu2>
  </gazebo>
  <!-- End of link list -->
  <!-- Joint list -->
  <!-- Joint proximal actuating hinge -->
  <joint name="gripperfinger_2_joint_proximal_actuating_hinge" type="revolute">
    <parent link="gripperfinger_2_link_0"/>
    <child link="gripperfinger_2_link_proximal_actuating_hinge"/>
    <axis xyz="0 0 1"/>
    <origin rpy="0 0 -2.0906" xyz="0 0 0.01"/>
    <limit effort="100" lower="-3.1416" upper="3.1416" velocity="100"/>
  </joint>
  <gazebo reference="gripperfinger_2_joint_proximal_actuating_hinge">
    <implicitSpringDamper>1</implicitSpringDamper>
  </gazebo>
  <!-- Joint paraproximal actuating hinge -->
  <joint name="gripperfinger_2_joint_paraproximal_actuating_hinge" type="revolute">
    <parent link="gripperfinger_2_link_0"/>
    <child link="gripperfinger_2_link_paraproximal_actuating_hinge"/>
    <axis xyz="0 0 1"/>
    <origin rpy="0 0 -2.0906" xyz="0 0 -0.01"/>
    <limit effort="100" lower="-3.1416" upper="3.1416" velocity="100"/>
  </joint>
  <gazebo reference="gripperfinger_2_joint_paraproximal_actuating_hinge">
    <implicitSpringDamper>1</implicitSpringDamper>
  </gazebo>
  <!-- Joint proximal actuating bar -->
  <joint name="gripperfinger_2_joint_proximal_actuating_bar" type="revolute">
    <parent link="gripperfinger_2_link_proximal_actuating_hinge"/>
    <child link="gripperfinger_2_link_proximal_actuating_bar"/>
    <axis xyz="0 0 1"/>
    <origin rpy="0 0 1.8616" xyz="0.02858 0 0"/>
    <limit effort="100" lower="-3.1416" upper="3.1416" velocity="100"/>
  </joint>
  <gazebo reference="gripperfinger_2_joint_proximal_actuating_bar">
    <implicitSpringDamper>1</implicitSpringDamper>
  </gazebo>
  <!-- Joint paraproximal bar -->
  <joint name="gripperfinger_2_joint_paraproximal_bar" type="revolute">
    <parent link="gripperfinger_2_link_paraproximal_actuating_hinge"/>
    <child link="gripperfinger_2_link_paraproximal_bar"/>
    <axis xyz="0 0 1"/>
    <origin rpy="0 0 1.57" xyz="0.02286 0 0"/>
    <limit effort="100" lower="-3.1416" upper="3.1416" velocity="100"/>
  </joint>
  <gazebo reference="gripperfinger_2_joint_paraproximal_bar">
    <implicitSpringDamper>1</implicitSpringDamper>
  </gazebo>
  <!-- Joint median actuating hinge -->
  <joint name="gripperfinger_2_joint_median_actuating_hinge" type="revolute">
    <parent link="gripperfinger_2_link_1"/>
    <child link="gripperfinger_2_link_median_actuating_hinge"/>
    <axis xyz="0 0 1"/>
    <origin rpy="0 0 -0.37" xyz="0 0.05715 0.01"/>
    <limit effort="100" lower="-3.1416" upper="3.1416" velocity="100"/>
  </joint>
  <gazebo reference="gripperfinger_2_joint_median_actuating_hinge">
    <implicitSpringDamper>1</implicitSpringDamper>
  </gazebo>
  <!-- Joint paramedian hinge -->
  <joint name="gripperfinger_2_joint_paramedian_hinge" type="revolute">
    <parent link="gripperfinger_2_link_1"/>
    <child link="gripperfinger_2_link_paramedian_hinge"/>
    <axis xyz="0 0 1"/>
    <!-- -0.37 is hand picked, 0.9719 is hand calculated from atan(0.02381/0.01625) -->
    <origin rpy="0 0 0" xyz="0 0.05715 -0.01"/>
    <limit effort="100" lower="-3.1416" upper="3.1416" velocity="100"/>
  </joint>
  <gazebo reference="gripperfinger_2_joint_paramedian_hinge">
    <implicitSpringDamper>1</implicitSpringDamper>
  </gazebo>
  <!-- Joint median actuating hinge median bar -->
  <joint name="gripperfinger_2_joint_median_actuating_hinge_median_bar" type="revolute">
    <parent link="gripperfinger_2_link_median_actuating_hinge"/>
    <child link="gripperfinger_2_link_median_bar"/>
    <axis xyz="0 0 1"/>
    <!-- hand calc 90 deg + atan(0.01516/0.01625) -->
    <origin rpy="0 0 2.3215" xyz="0.01625 0.01516 0"/>
    <limit effort="100" lower="-3.1416" upper="3.1416" velocity="100"/>
  </joint>
  <gazebo reference="gripperfinger_2_joint_median_actuating_hinge_median_bar">
    <implicitSpringDamper>1</implicitSpringDamper>
  </gazebo>
  <!-- Joint paradistal hinge -->
  <joint name="gripperfinger_2_joint_paradistal_hinge" type="revolute">
    <parent link="gripperfinger_2_link_2"/>
    <child link="gripperfinger_2_link_paradistal_hinge"/>
    <axis xyz="0 0 1"/>
    <origin rpy="0 0 0" xyz="0 0.039 -0.01"/>
    <limit effort="100" lower="-3.1416" upper="3.1416" velocity="100"/>
  </joint>
  <gazebo reference="gripperfinger_2_joint_paradistal_hinge">
    <implicitSpringDamper>1</implicitSpringDamper>
  </gazebo>
  <!-- Joint paramedian hinge median bar underactuated -->
  <joint name="gripperfinger_2_joint_paramedian_hinge_median_bar_underactuated" type="revolute">
    <parent link="gripperfinger_2_link_paramedian_hinge"/>
    <child link="gripperfinger_2_link_median_bar_underactuated"/>
    <axis xyz="0 0 1"/>
    <!-- hand calc 90 deg + atan(0.01227/0.00329) -->
    <origin rpy="0 0 1.5708" xyz="0.01227 0.00329 0"/>
    <limit effort="100" lower="-3.1416" upper="3.1416" velocity="100"/>
  </joint>
  <gazebo reference="gripperfinger_2_joint_paramedian_hinge_median_bar_underactuated">
    <implicitSpringDamper>1</implicitSpringDamper>
  </gazebo>
  <!-- Joint 1 -->
  <joint name="gripperfinger_2_joint_1" type="revolute">
    <origin rpy="0 0 -2.0906" xyz="0 0 0"/>
    <axis xyz="0 0 1"/>
    <parent link="gripperfinger_2_link_0"/>
    <child link="gripperfinger_2_link_1"/>
    <dynamics damping="1" friction="0"/>
    <!-- Limits: [0deg.,70deg.] -->
    <limit effort="60" lower="0" upper="1.2217" velocity="-1"/>
  </joint>
  <gazebo reference="gripperfinger_2_joint_1">
    <implicitSpringDamper>1</implicitSpringDamper>
  </gazebo>
  <!-- Joint 2 -->
  <joint name="gripperfinger_2_joint_2" type="revolute">
    <parent link="gripperfinger_2_link_1"/>
    <child link="gripperfinger_2_link_2"/>
    <dynamics damping="1" friction="0"/>
    <axis xyz="0 0 1"/>
    <origin rpy="0 0 0" xyz="0 0.05715 0"/>
    <!-- Limits: [0deg.,90deg.] -->
    <limit effort="60" lower="0" upper="1.5708" velocity="-1"/>
  </joint>
  <gazebo reference="gripperfinger_2_joint_2">
    <implicitSpringDamper>1</implicitSpringDamper>
  </gazebo>
  <!-- Joint 3 -->
  <joint name="gripperfinger_2_joint_3" type="revolute">
    <parent link="gripperfinger_2_link_2"/>
    <child link="gripperfinger_2_link_3"/>
    <dynamics damping="1" friction="0"/>
    <axis xyz="0 0 1"/>
    <origin rpy="0 0 2.0906" xyz="0 0.039 0"/>
    <!-- Limits: [-38deg.,60deg.] -->
    <limit effort="60" lower="-0.6632" upper="1.0471" velocity="-1"/>
  </joint>
  <gazebo reference="gripperfinger_2_joint_3">
    <implicitSpringDamper>1</implicitSpringDamper>
  </gazebo>
  <!-- end of joint list -->
  <!-- coupling joints in sdf -->
  <gazebo>
    <joint name="gripperfinger_2_link_proximal_actuating_bar_median_actuating_hinge_couple" type="revolute">
      <parent>gripperfinger_2_link_median_actuating_hinge</parent>
      <child>gripperfinger_2_link_proximal_actuating_bar</child>
      <pose>0.05398 0 0 0 0 0</pose>
      <axis>
        <dynamics>
          <damping>0</damping>
          <friction>0</friction>
        </dynamics>
        <xyz>0 0 1</xyz>
        <!-- <use_parent_model_frame>false</use_parent_model_frame> -->
      </axis>
    </joint>
  </gazebo>
  <gazebo reference="gripperfinger_2_link_proximal_actuating_bar_median_actuating_hinge_couple">
    <implicitSpringDamper>1</implicitSpringDamper>
  </gazebo>
  <gazebo>
    <joint name="gripperfinger_2_link_median_bar_link_3_couple" type="revolute">
      <parent>gripperfinger_2_link_3</parent>
      <child>gripperfinger_2_link_median_bar</child>
      <pose>0.0381 0 0 0 0 0</pose>
      <axis>
        <dynamics>
          <damping>0</damping>
          <friction>0</friction>
        </dynamics>
        <xyz>0 0 1</xyz>
        <!-- <use_parent_model_frame>false</use_parent_model_frame> -->
      </axis>
    </joint>
  </gazebo>
  <gazebo reference="gripperfinger_2_link_median_bar_link_3_couple">
    <implicitSpringDamper>1</implicitSpringDamper>
  </gazebo>
  <gazebo>
    <joint name="gripperfinger_2_link_paramedian_bar_paradistal_hinge_couple" type="revolute">
      <parent>gripperfinger_2_link_paradistal_hinge</parent>
      <child>gripperfinger_2_link_median_bar_underactuated</child>
      <pose>0.0381 0 0 0 0 0</pose>
      <axis>
        <dynamics>
          <damping>0</damping>
          <friction>0</friction>
        </dynamics>
        <xyz>0 0 1</xyz>
        <!-- <use_parent_model_frame>false</use_parent_model_frame> -->
      </axis>
    </joint>
  </gazebo>
  <gazebo reference="gripperfinger_2_link_median_bar_link_3_couple">
    <implicitSpringDamper>1</implicitSpringDamper>
  </gazebo>
  <gazebo>
    <joint name="gripperfinger_2_link_paradistal_hinge_link_3_couple" type="revolute">
      <parent>gripperfinger_2_link_paradistal_hinge</parent>
      <child>gripperfinger_2_link_3</child>
      <pose>0.0381 0 0 0 0 0</pose>
      <axis>
        <dynamics>
          <damping>0</damping>
          <friction>0</friction>
        </dynamics>
        <xyz>0 0 1</xyz>
        <!-- <use_parent_model_frame>false</use_parent_model_frame> -->
      </axis>
    </joint>
  </gazebo>
  <gazebo reference="gripperfinger_2_link_paradistal_hinge_link_3_couple">
    <implicitSpringDamper>1</implicitSpringDamper>
  </gazebo>
  <gazebo>
    <joint name="gripperfinger_2_link_paraproximal_bar_paramedian_hinge_couple" type="revolute">
      <parent>gripperfinger_2_link_paramedian_hinge</parent>
      <child>gripperfinger_2_link_paraproximal_bar</child>
      <pose>0.05770 0 0 0 0 0</pose>
      <axis>
        <dynamics>
          <damping>0</damping>
          <friction>0</friction>
        </dynamics>
        <xyz>0 0 1</xyz>
        <!-- <use_parent_model_frame>false</use_parent_model_frame> -->
      </axis>
    </joint>
  </gazebo>
  <gazebo reference="gripperfinger_2_link_paraproximal_bar_paramedian_hinge_couple">
    <implicitSpringDamper>1</implicitSpringDamper>
  </gazebo>
  <!-- Link list -->
  <!-- Link 0 -->
  <link name="gripperfinger_middle_link_0">
    <visual>
      <origin rpy="0 0 0" xyz="0 0 0"/>
      <geometry>
        <mesh filename="package://robotiq_s_model_visualization/meshes/s-model_articulated/visual/link_0.STL"/>
      </geometry>
      <material name="green">
        <color rgba="0 1 0 1"/>
      </material>
    </visual>
    <collision>
      <origin rpy="0 0 0" xyz="0 0 0"/>
      <geometry>
        <mesh filename="package://robotiq_s_model_visualization/meshes/s-model_articulated/collision/link_0.STL"/>
      </geometry>
      <material name="yellow">
        <color rgba="0 1 1 1"/>
      </material>
    </collision>
    <inertial>
      <mass value="0.1"/>
      <origin xyz="-0.01 0 0"/>
      <inertia ixx="0.000018" ixy="0" ixz="0" iyy="0.000025" iyz="0" izz="0.000025"/>
    </inertial>
  </link>
  <gazebo reference="gripperfinger_middle_link_0">
    <mu1>1.1</mu1>
    <mu2>1.1</mu2>
  </gazebo>
  <!-- Link 1 -->
  <link name="gripperfinger_middle_link_1">
    <visual>
      <origin rpy="0 0 1.5708" xyz="0 0.05717 0"/>
      <geometry>
        <mesh filename="package://robotiq_s_model_visualization/meshes/s-model_articulated/visual/link_1.STL"/>
      </geometry>
      <material name="green"/>
    </visual>
    <collision>
      <origin rpy="0 0 1.5708" xyz="0 0.05717 0"/>
      <geometry>
        <mesh filename="package://robotiq_s_model_visualization/meshes/s-model_articulated/collision/link_1.STL"/>
      </geometry>
      <material name="yellow">
        <color rgba="0 1 1 1"/>
      </material>
    </collision>
    <inertial>
      <origin rpy="0 0 1.5708" xyz="0.00053 0.03218 0"/>
      <mass value="0.047"/>
      <inertia ixx="0.00000499332" ixy="0.00000091312" ixz="-0.00000000120" iyy="0.00006434531" iyz="-0.00000000007" izz="0.00006061917"/>
    </inertial>
  </link>
  <gazebo reference="gripperfinger_middle_link_1">
    <mu1>1.1</mu1>
    <mu2>1.1</mu2>
  </gazebo>
  <!-- Link 2 -->
  <link name="gripperfinger_middle_link_2">
    <visual>
      <origin rpy="0 0 1.5708" xyz="0 0.03810 0.0075"/>
      <geometry>
        <mesh filename="package://robotiq_s_model_visualization/meshes/s-model_articulated/visual/link_2.STL"/>
      </geometry>
      <material name="green"/>
    </visual>
    <collision>
      <origin rpy="0 0 1.5708" xyz="0 0.03810 0.0075"/>
      <geometry>
        <mesh filename="package://robotiq_s_model_visualization/meshes/s-model_articulated/collision/link_2.STL"/>
      </geometry>
      <material name="yellow"/>
    </collision>
    <inertial>
      <origin rpy="0 0 1.5708" xyz="0.00048 0.02167 0.00018"/>
      <mass value="0.03284"/>
      <inertia ixx="0.00000348008" ixy="0.00000031940" ixz="0.00000013041" iyy="0.00002248123" iyz="0.00000000291" izz="0.00001986346"/>
    </inertial>
  </link>
  <gazebo reference="gripperfinger_middle_link_2">
    <mu1>1.1</mu1>
    <mu2>1.1</mu2>
  </gazebo>
  <!-- Link 3 -->
  <link name="gripperfinger_middle_link_3">
    <visual>
      <origin rpy="0 0 0" xyz="0 0 0"/>
      <geometry>
        <mesh filename="package://robotiq_s_model_visualization/meshes/s-model_articulated/visual/link_3.STL"/>
      </geometry>
      <material name="green"/>
    </visual>
    <collision>
      <origin rpy="0 0 0" xyz="0 0 0"/>
      <geometry>
        <mesh filename="package://robotiq_s_model_visualization/meshes/s-model_articulated/collision/link_3.STL"/>
      </geometry>
      <material name="yellow"/>
    </collision>
    <inertial>
      <origin rpy="0 0 0" xyz="0.01626 0.00049 0.0002"/>
      <mass value="0.03354"/>
      <inertia ixx="0.00000305151" ixy="0.00000089792" ixz="0.00000000249" iyy="0.00001427978" iyz="-0.00000001191" izz="0.00001264126"/>
    </inertial>
  </link>
  <gazebo reference="gripperfinger_middle_link_3">
    <mu1>1.1</mu1>
    <mu2>1.1</mu2>
  </gazebo>
  <!-- Link proximal actuating hinge -->
  <link name="gripperfinger_middle_link_proximal_actuating_hinge">
    <visual>
      <origin rpy="0 0 0" xyz="0.01429 0 0"/>
      <geometry>
        <box size="0.02858 .0075 .002"/>
      </geometry>
    </visual>
    <collision>
      <origin rpy="0 0 0" xyz="0.01429 0 0"/>
      <geometry>
        <box size="0.02858 .0075 .002"/>
      </geometry>
    </collision>
    <inertial>
      <origin rpy="0 0 0" xyz="0.0012 -0.00162 -0.00161"/>
      <mass value="0.02647"/>
      <inertia ixx="0.00000156447" ixy="0.000000236226" ixz="-0.00000014862" iyy="0.00000221068" iyz="-0.00000014369" izz="0.00000323175"/>
    </inertial>
  </link>
  <gazebo reference="gripperfinger_middle_link_proximal_actuating_hinge">
    <mu1>1.1</mu1>
    <mu2>1.1</mu2>
  </gazebo>
  <!-- Link paraproximal actuating hinge -->
  <link name="gripperfinger_middle_link_paraproximal_actuating_hinge">
    <visual>
      <origin rpy="0 0 0" xyz="0.01143 0 0"/>
      <geometry>
        <box size="0.02286 .0075 .002"/>
      </geometry>
    </visual>
    <collision>
      <origin rpy="0 0 0" xyz="0.01143 0 0"/>
      <geometry>
        <box size="0.02286 .0075 .002"/>
      </geometry>
    </collision>
    <inertial>
      <origin rpy="0 0 0" xyz="0.0064 0 0"/>
      <!-- copied from proximal_actuating_hinge -->
      <mass value="0.00362"/>
      <inertia ixx="0.00000012043" ixy="0" ixz="0" iyy="0.00000053588" iyz="0" izz="0.00000065322"/>
    </inertial>
  </link>
  <gazebo reference="gripperfinger_middle_link_paraproximal_actuating_hinge">
    <mu1>1.1</mu1>
    <mu2>1.1</mu2>
  </gazebo>
  <!-- Link proximal actuating bar -->
  <link name="gripperfinger_middle_link_proximal_actuating_bar">
    <visual>
      <origin rpy="0 0 0" xyz="0.026789 0 0"/>
      <geometry>
        <box size="0.05398 .0075 .002"/>
      </geometry>
    </visual>
    <collision>
      <origin rpy="0 0 0" xyz="0.026789 0 0"/>
      <geometry>
        <box size="0.05398 .0075 .002"/>
      </geometry>
    </collision>
    <inertial>
      <origin rpy="0 0 0" xyz="0.02699 -0.00122 0"/>
      <mass value="0.00659"/>
      <inertia ixx="0.00000008348" ixy="-0.0000002179" ixz="0.00000000134" iyy="0.00000719076" iyz="0" izz="0.00000718272"/>
    </inertial>
  </link>
  <gazebo reference="gripperfinger_middle_link_proximal_actuating_bar">
    <mu1>1.1</mu1>
    <mu2>1.1</mu2>
  </gazebo>
  <!-- Link paraproximal bar -->
  <link name="gripperfinger_middle_link_paraproximal_bar">
    <visual>
      <origin rpy="0 0 0" xyz="0.02885 0 0"/>
      <geometry>
        <box size="0.05770 .0075 .002"/>
      </geometry>
    </visual>
    <collision>
      <origin rpy="0 0 0" xyz="0.02885 0 0"/>
      <geometry>
        <box size="0.05770 .0075 .002"/>
      </geometry>
    </collision>
    <inertial>
      <origin rpy="0 0 0" xyz="0.02858 -0.00129 0"/>
      <mass value="0.00732"/>
      <inertia ixx="0.00000009065" ixy="-0.00000027047" ixz="0.00000000142" iyy="0.00000878034" iyz="0" izz="0.00000877558"/>
    </inertial>
  </link>
  <gazebo reference="gripperfinger_middle_link_paraproximal_bar">
    <mu1>1.1</mu1>
    <mu2>1.1</mu2>
  </gazebo>
  <!-- Link median actuating hinge -->
  <link name="gripperfinger_middle_link_median_actuating_hinge">
    <visual>
      <origin rpy="0 0 0" xyz="0 0 0"/>
      <geometry>
        <box size=".02 .02 .002"/>
      </geometry>
    </visual>
    <collision>
      <origin rpy="0 0 0" xyz="0 0 0"/>
      <geometry>
        <box size=".02 .02 .002"/>
      </geometry>
    </collision>
    <inertial>
      <origin rpy="0 0 0" xyz="0.0092 0.00514 0"/>
      <mass value="0.00359"/>
      <inertia ixx="0.00000024735" ixy="0.00000023619" ixz="0" iyy="0.00000047681" iyz="0" izz="0.00000071813"/>
    </inertial>
  </link>
  <gazebo reference="gripperfinger_middle_link_median_actuating_hinge">
    <mu1>1.1</mu1>
    <mu2>1.1</mu2>
  </gazebo>
  <!-- Link median bar -->
  <link name="gripperfinger_middle_link_median_bar">
    <visual>
      <origin rpy="0 0 0" xyz="0.01905 0 0"/>
      <geometry>
        <box size="0.0381 .0075 .002"/>
      </geometry>
    </visual>
    <collision>
      <origin rpy="0 0 0" xyz="0.01905 0 0"/>
      <geometry>
        <box size="0.0381 .0075 .002"/>
      </geometry>
    </collision>
    <inertial>
      <origin rpy="0 0 0" xyz="0.01905 -0.00107 0"/>
      <mass value="0.00538"/>
      <inertia ixx="0.00000006639" ixy="-0.00000010996" ixz="0.00000000094" iyy="0.00000305318" iyz="0" izz="0.00000304657"/>
    </inertial>
  </link>
  <gazebo reference="gripperfinger_middle_link_median_bar">
    <mu1>1.1</mu1>
    <mu2>1.1</mu2>
  </gazebo>
  <!-- Link paramedian hinge -->
  <link name="gripperfinger_middle_link_paramedian_hinge">
    <visual>
      <origin rpy="0 0 0" xyz="0 0 0"/>
      <geometry>
        <box size=".02 .02 .002"/>
      </geometry>
    </visual>
    <collision>
      <origin rpy="0 0 0" xyz="0 0 0"/>
      <geometry>
        <box size=".02 .02 .002"/>
      </geometry>
    </collision>
    <inertial>
      <origin rpy="0 0 0" xyz="-0.01025 0.00046 0"/>
      <mass value="0.00276"/>
      <inertia ixx="0.00000004213" ixy="-0.00000001491" ixz="0" iyy="0.00000050258" iyz="0" izz="0.00000054007"/>
    </inertial>
  </link>
  <gazebo reference="gripperfinger_middle_link_paramedian_hinge">
    <mu1>1.1</mu1>
    <mu2>1.1</mu2>
  </gazebo>
  <!-- Link median bar underactuated -->
  <link name="gripperfinger_middle_link_median_bar_underactuated">
    <visual>
      <origin rpy="0 0 0" xyz="0.01905 0 0"/>
      <geometry>
        <box size="0.0381 .0075 .002"/>
      </geometry>
    </visual>
    <collision>
      <origin rpy="0 0 0" xyz="0.01905 0 0"/>
      <geometry>
        <box size="0.0381 .0075 .002"/>
      </geometry>
    </collision>
    <inertial>
      <origin rpy="0 0 0" xyz="0.01905 -0.00107 0"/>
      <mass value="0.00538"/>
      <inertia ixx="0.00000006639" ixy="-0.00000010996" ixz="-0.00000000094" iyy="0.00000305318" iyz="0" izz="0.00000304657"/>
    </inertial>
  </link>
  <gazebo reference="gripperfinger_middle_link_median_bar_underactuated">
    <mu1>1.1</mu1>
    <mu2>1.1</mu2>
  </gazebo>
  <!-- Link paradistal hinge -->
  <link name="gripperfinger_middle_link_paradistal_hinge">
    <visual>
      <origin rpy="0 0 0" xyz="0 0 0"/>
      <geometry>
        <box size=".02 .02 .002"/>
      </geometry>
    </visual>
    <collision>
      <origin rpy="0 0 0" xyz="0 0 0"/>
      <geometry>
        <box size=".02 0.02 .002"/>
      </geometry>
    </collision>
    <inertial>
      <origin rpy="0 0 0" xyz="0.00548 0 0"/>
      <mass value="0.00158"/>
      <inertia ixx="0.00000001907" ixy="0" ixz="0" iyy="0.00000010970" iyz="0" izz="0.00000012610"/>
    </inertial>
  </link>
  <gazebo reference="gripperfinger_middle_link_paradistal_hinge">
    <mu1>1.1</mu1>
    <mu2>1.1</mu2>
  </gazebo>
  <!-- End of link list -->
  <!-- Joint list -->
  <!-- Joint proximal actuating hinge -->
  <joint name="gripperfinger_middle_joint_proximal_actuating_hinge" type="revolute">
    <parent link="gripperfinger_middle_link_0"/>
    <child link="gripperfinger_middle_link_proximal_actuating_hinge"/>
    <axis xyz="0 0 1"/>
    <origin rpy="0 0 -2.0906" xyz="0 0 0.01"/>
    <limit effort="100" lower="-3.1416" upper="3.1416" velocity="100"/>
  </joint>
  <gazebo reference="gripperfinger_middle_joint_proximal_actuating_hinge">
    <implicitSpringDamper>1</implicitSpringDamper>
  </gazebo>
  <!-- Joint paraproximal actuating hinge -->
  <joint name="gripperfinger_middle_joint_paraproximal_actuating_hinge" type="revolute">
    <parent link="gripperfinger_middle_link_0"/>
    <child link="gripperfinger_middle_link_paraproximal_actuating_hinge"/>
    <axis xyz="0 0 1"/>
    <origin rpy="0 0 -2.0906" xyz="0 0 -0.01"/>
    <limit effort="100" lower="-3.1416" upper="3.1416" velocity="100"/>
  </joint>
  <gazebo reference="gripperfinger_middle_joint_paraproximal_actuating_hinge">
    <implicitSpringDamper>1</implicitSpringDamper>
  </gazebo>
  <!-- Joint proximal actuating bar -->
  <joint name="gripperfinger_middle_joint_proximal_actuating_bar" type="revolute">
    <parent link="gripperfinger_middle_link_proximal_actuating_hinge"/>
    <child link="gripperfinger_middle_link_proximal_actuating_bar"/>
    <axis xyz="0 0 1"/>
    <origin rpy="0 0 1.8616" xyz="0.02858 0 0"/>
    <limit effort="100" lower="-3.1416" upper="3.1416" velocity="100"/>
  </joint>
  <gazebo reference="gripperfinger_middle_joint_proximal_actuating_bar">
    <implicitSpringDamper>1</implicitSpringDamper>
  </gazebo>
  <!-- Joint paraproximal bar -->
  <joint name="gripperfinger_middle_joint_paraproximal_bar" type="revolute">
    <parent link="gripperfinger_middle_link_paraproximal_actuating_hinge"/>
    <child link="gripperfinger_middle_link_paraproximal_bar"/>
    <axis xyz="0 0 1"/>
    <origin rpy="0 0 1.57" xyz="0.02286 0 0"/>
    <limit effort="100" lower="-3.1416" upper="3.1416" velocity="100"/>
  </joint>
  <gazebo reference="gripperfinger_middle_joint_paraproximal_bar">
    <implicitSpringDamper>1</implicitSpringDamper>
  </gazebo>
  <!-- Joint median actuating hinge -->
  <joint name="gripperfinger_middle_joint_median_actuating_hinge" type="revolute">
    <parent link="gripperfinger_middle_link_1"/>
    <child link="gripperfinger_middle_link_median_actuating_hinge"/>
    <axis xyz="0 0 1"/>
    <origin rpy="0 0 -0.37" xyz="0 0.05715 0.01"/>
    <limit effort="100" lower="-3.1416" upper="3.1416" velocity="100"/>
  </joint>
  <gazebo reference="gripperfinger_middle_joint_median_actuating_hinge">
    <implicitSpringDamper>1</implicitSpringDamper>
  </gazebo>
  <!-- Joint paramedian hinge -->
  <joint name="gripperfinger_middle_joint_paramedian_hinge" type="revolute">
    <parent link="gripperfinger_middle_link_1"/>
    <child link="gripperfinger_middle_link_paramedian_hinge"/>
    <axis xyz="0 0 1"/>
    <!-- -0.37 is hand picked, 0.9719 is hand calculated from atan(0.02381/0.01625) -->
    <origin rpy="0 0 0" xyz="0 0.05715 -0.01"/>
    <limit effort="100" lower="-3.1416" upper="3.1416" velocity="100"/>
  </joint>
  <gazebo reference="gripperfinger_middle_joint_paramedian_hinge">
    <implicitSpringDamper>1</implicitSpringDamper>
  </gazebo>
  <!-- Joint median actuating hinge median bar -->
  <joint name="gripperfinger_middle_joint_median_actuating_hinge_median_bar" type="revolute">
    <parent link="gripperfinger_middle_link_median_actuating_hinge"/>
    <child link="gripperfinger_middle_link_median_bar"/>
    <axis xyz="0 0 1"/>
    <!-- hand calc 90 deg + atan(0.01516/0.01625) -->
    <origin rpy="0 0 2.3215" xyz="0.01625 0.01516 0"/>
    <limit effort="100" lower="-3.1416" upper="3.1416" velocity="100"/>
  </joint>
  <gazebo reference="gripperfinger_middle_joint_median_actuating_hinge_median_bar">
    <implicitSpringDamper>1</implicitSpringDamper>
  </gazebo>
  <!-- Joint paradistal hinge -->
  <joint name="gripperfinger_middle_joint_paradistal_hinge" type="revolute">
    <parent link="gripperfinger_middle_link_2"/>
    <child link="gripperfinger_middle_link_paradistal_hinge"/>
    <axis xyz="0 0 1"/>
    <origin rpy="0 0 0" xyz="0 0.039 -0.01"/>
    <limit effort="100" lower="-3.1416" upper="3.1416" velocity="100"/>
  </joint>
  <gazebo reference="gripperfinger_middle_joint_paradistal_hinge">
    <implicitSpringDamper>1</implicitSpringDamper>
  </gazebo>
  <!-- Joint paramedian hinge median bar underactuated -->
  <joint name="gripperfinger_middle_joint_paramedian_hinge_median_bar_underactuated" type="revolute">
    <parent link="gripperfinger_middle_link_paramedian_hinge"/>
    <child link="gripperfinger_middle_link_median_bar_underactuated"/>
    <axis xyz="0 0 1"/>
    <!-- hand calc 90 deg + atan(0.01227/0.00329) -->
    <origin rpy="0 0 1.5708" xyz="0.01227 0.00329 0"/>
    <limit effort="100" lower="-3.1416" upper="3.1416" velocity="100"/>
  </joint>
  <gazebo reference="gripperfinger_middle_joint_paramedian_hinge_median_bar_underactuated">
    <implicitSpringDamper>1</implicitSpringDamper>
  </gazebo>
  <!-- Joint 1 -->
  <joint name="gripperfinger_middle_joint_1" type="revolute">
    <origin rpy="0 0 -2.0906" xyz="0 0 0"/>
    <axis xyz="0 0 1"/>
    <parent link="gripperfinger_middle_link_0"/>
    <child link="gripperfinger_middle_link_1"/>
    <dynamics damping="1" friction="0"/>
    <!-- Limits: [0deg.,70deg.] -->
    <limit effort="60" lower="0" upper="1.2217" velocity="-1"/>
  </joint>
  <gazebo reference="gripperfinger_middle_joint_1">
    <implicitSpringDamper>1</implicitSpringDamper>
  </gazebo>
  <!-- Joint 2 -->
  <joint name="gripperfinger_middle_joint_2" type="revolute">
    <parent link="gripperfinger_middle_link_1"/>
    <child link="gripperfinger_middle_link_2"/>
    <dynamics damping="1" friction="0"/>
    <axis xyz="0 0 1"/>
    <origin rpy="0 0 0" xyz="0 0.05715 0"/>
    <!-- Limits: [0deg.,90deg.] -->
    <limit effort="60" lower="0" upper="1.5708" velocity="-1"/>
  </joint>
  <gazebo reference="gripperfinger_middle_joint_2">
    <implicitSpringDamper>1</implicitSpringDamper>
  </gazebo>
  <!-- Joint 3 -->
  <joint name="gripperfinger_middle_joint_3" type="revolute">
    <parent link="gripperfinger_middle_link_2"/>
    <child link="gripperfinger_middle_link_3"/>
    <dynamics damping="1" friction="0"/>
    <axis xyz="0 0 1"/>
    <origin rpy="0 0 2.0906" xyz="0 0.039 0"/>
    <!-- Limits: [-38deg.,60deg.] -->
    <limit effort="60" lower="-0.6632" upper="1.0471" velocity="-1"/>
  </joint>
  <gazebo reference="gripperfinger_middle_joint_3">
    <implicitSpringDamper>1</implicitSpringDamper>
  </gazebo>
  <!-- end of joint list -->
  <!-- coupling joints in sdf -->
  <gazebo>
    <joint name="gripperfinger_middle_link_proximal_actuating_bar_median_actuating_hinge_couple" type="revolute">
      <parent>gripperfinger_middle_link_median_actuating_hinge</parent>
      <child>gripperfinger_middle_link_proximal_actuating_bar</child>
      <pose>0.05398 0 0 0 0 0</pose>
      <axis>
        <dynamics>
          <damping>0</damping>
          <friction>0</friction>
        </dynamics>
        <xyz>0 0 1</xyz>
        <!-- <use_parent_model_frame>false</use_parent_model_frame> -->
      </axis>
    </joint>
  </gazebo>
  <gazebo reference="gripperfinger_middle_link_proximal_actuating_bar_median_actuating_hinge_couple">
    <implicitSpringDamper>1</implicitSpringDamper>
  </gazebo>
  <gazebo>
    <joint name="gripperfinger_middle_link_median_bar_link_3_couple" type="revolute">
      <parent>gripperfinger_middle_link_3</parent>
      <child>gripperfinger_middle_link_median_bar</child>
      <pose>0.0381 0 0 0 0 0</pose>
      <axis>
        <dynamics>
          <damping>0</damping>
          <friction>0</friction>
        </dynamics>
        <xyz>0 0 1</xyz>
        <!-- <use_parent_model_frame>false</use_parent_model_frame> -->
      </axis>
    </joint>
  </gazebo>
  <gazebo reference="gripperfinger_middle_link_median_bar_link_3_couple">
    <implicitSpringDamper>1</implicitSpringDamper>
  </gazebo>
  <gazebo>
    <joint name="gripperfinger_middle_link_paramedian_bar_paradistal_hinge_couple" type="revolute">
      <parent>gripperfinger_middle_link_paradistal_hinge</parent>
      <child>gripperfinger_middle_link_median_bar_underactuated</child>
      <pose>0.0381 0 0 0 0 0</pose>
      <axis>
        <dynamics>
          <damping>0</damping>
          <friction>0</friction>
        </dynamics>
        <xyz>0 0 1</xyz>
        <!-- <use_parent_model_frame>false</use_parent_model_frame> -->
      </axis>
    </joint>
  </gazebo>
  <gazebo reference="gripperfinger_middle_link_median_bar_link_3_couple">
    <implicitSpringDamper>1</implicitSpringDamper>
  </gazebo>
  <gazebo>
    <joint name="gripperfinger_middle_link_paradistal_hinge_link_3_couple" type="revolute">
      <parent>gripperfinger_middle_link_paradistal_hinge</parent>
      <child>gripperfinger_middle_link_3</child>
      <pose>0.0381 0 0 0 0 0</pose>
      <axis>
        <dynamics>
          <damping>0</damping>
          <friction>0</friction>
        </dynamics>
        <xyz>0 0 1</xyz>
        <!-- <use_parent_model_frame>false</use_parent_model_frame> -->
      </axis>
    </joint>
  </gazebo>
  <gazebo reference="gripperfinger_middle_link_paradistal_hinge_link_3_couple">
    <implicitSpringDamper>1</implicitSpringDamper>
  </gazebo>
  <gazebo>
    <joint name="gripperfinger_middle_link_paraproximal_bar_paramedian_hinge_couple" type="revolute">
      <parent>gripperfinger_middle_link_paramedian_hinge</parent>
      <child>gripperfinger_middle_link_paraproximal_bar</child>
      <pose>0.05770 0 0 0 0 0</pose>
      <axis>
        <dynamics>
          <damping>0</damping>
          <friction>0</friction>
        </dynamics>
        <xyz>0 0 1</xyz>
        <!-- <use_parent_model_frame>false</use_parent_model_frame> -->
      </axis>
    </joint>
  </gazebo>
  <gazebo reference="gripperfinger_middle_link_paraproximal_bar_paramedian_hinge_couple">
    <implicitSpringDamper>1</implicitSpringDamper>
  </gazebo>
  <!-- link list -->
  <!-- Link palm -->
  <link name="gripperpalm">
    <visual>
      <geometry>
        <mesh filename="package://robotiq_s_model_visualization/meshes/s-model_articulated/visual/palm.STL"/>
      </geometry>
      <material name="green">
        <color rgba="0 1 0 1"/>
      </material>
    </visual>
    <!-- Simple shape collision -->
    <collision>
      <origin rpy="0 0 0" xyz="0 0 0"/>
      <geometry>
        <box size="0.1 0.1 0.1"/>
      </geometry>
      <material name="yellow">
        <color rgba="0 1 1 1"/>
      </material>
    </collision>
    <inertial>
      <origin rpy="0 0 0" xyz="0 0 0"/>
      <mass value="1.3"/>
      <inertia ixx="0.0035" ixy="0" ixz="-0" iyy="0.0035" iyz="0" izz="0.0035"/>
    </inertial>
  </link>
  <gazebo reference="gripperpalm">
    <mu1>1.1</mu1>
    <mu2>1.1</mu2>
  </gazebo>
  <!-- End of link list -->
  <!-- Joint list -->
  <!-- Joint palm_finger_1_joint -->
  <joint name="gripperpalm_finger_1_joint" type="revolute">
    <parent link="gripperpalm"/>
    <child link="gripperfinger_1_link_0"/>
    <dynamics damping="1" friction="0"/>
    <axis xyz="0 1 0"/>
    <origin rpy="0 3.1416 -1.57" xyz="-0.0455 0.0214 0.036"/>
    <!-- Limits: [-17deg.,17deg.] -->
    <limit effort="60" lower="-0.2967" upper="0.2967" velocity="-1"/>
  </joint>
  <gazebo reference="gripperpalm_finger_1_joint">
    <implicitSpringDamper>1</implicitSpringDamper>
  </gazebo>
  <!-- Joint palm_finger_2_joint -->
  <joint name="gripperpalm_finger_2_joint" type="revolute">
    <parent link="gripperpalm"/>
    <child link="gripperfinger_2_link_0"/>
    <dynamics damping="1" friction="0"/>
    <axis xyz="0 1 0"/>
    <origin rpy="0 3.1416 -1.57" xyz="-0.0455 0.0214 -0.036"/>
    <!-- Limits: [-17deg.,17deg.] -->
    <limit effort="60" lower="-0.2967" upper="0.2967" velocity="-1"/>
  </joint>
  <gazebo reference="gripperpalm_finger_2_joint">
    <implicitSpringDamper>1</implicitSpringDamper>
  </gazebo>
  <!-- Joint palm_finger_middle_joint -->
  <joint name="gripperpalm_finger_middle_joint" type="revolute">
    <parent link="gripperpalm"/>
    <child link="gripperfinger_middle_link_0"/>
    <dynamics damping="1" friction="0"/>
    <axis xyz="0 1 0"/>
    <origin rpy="0 0 1.57" xyz="0.0455 0.0214 0"/>
    <limit effort="60" lower="0" upper="0" velocity="-1"/>
  </joint>
  <gazebo reference="gripperpalm_finger_middle_joint">
    <implicitSpringDamper>1</implicitSpringDamper>
  </gazebo>
  <!-- end of joint list -->
</robot>

