<!--

MODEL: Univewrsal Robots UR5 + Robotiq S Model 3 Finger Gripper
AUTHOR: Andrea Franceschetti @IASLAB Research Group
UNIVERSITY: University of Padua
DEPARTMENT: Departement of Information Engineering DEI
Control Engineering / Automation Engineering

-->


<!--Link  MuJoCo modeling: http://www.mujoco.org/book/modeling.html-->

<mujoco model="ur5gripper">
    <compiler angle="radian"
              inertiafromgeom="true"
              texturedir="textures/"
              meshdir="mesh/visual/"/>
    <option timestep="2e-3"
            iterations="10"
            tolerance="1e-10"
            impratio="20"/>
    <size njmax="600" nconmax="150" nstack="300000"/>

    <default>
        <site rgba="0.8 0.6 0.7 0.3" type="ellipsoid" group="3"/>
        <geom contype='1' conaffinity='1' condim='4'  margin="1e-3" solref=".01 1" solimp=".99 .99 .01" />
        <joint armature="0.01" damping=".1"/>
        <default class="UR5">
            <joint damping='65'/>
        </default>
        <default class="UR5e">
            <joint damping='45'/>
        </default>
        <default class="GRIPPER">
            <joint damping='5'/>
        </default>
    </default>

    <visual>
        <map fogstart="3" fogend="5" znear="0.05"/>
        <quality shadowsize="2048"/>
        <scale framelength="0.1"
               framewidth="0.005"
               contactwidth="0.1"
               contactheight="0.005"
               forcewidth="0.01"
               />
    </visual>

    <!--Assets-->
    <asset>
        <!--Meshes-->
        <mesh name="base"           file="base.stl"     />
        <mesh name="shoulder"       file="shoulder.stl" />
        <mesh name="upperarm"       file="upperarm.stl" />
        <mesh name="forearm"        file="forearm.stl"  />
        <mesh name="wrist1"         file="wrist1.stl"   />
        <mesh name="wrist2"         file="wrist2.stl"   />
        <mesh name="wrist3"         file="wrist3.stl"   />
        <mesh name="gripperpalm"    file="palm.STL"     />
        <mesh name="link_0"         file="link_0.STL"   />
        <mesh name="link_1"         file="link_1.STL"   />
        <mesh name="link_2"         file="link_2.STL"   />
        <mesh name="link_3"         file="link_3.STL"   />

        <mesh name="robotiq_85_base_link_coarse" file="robotiq_85_base_link_coarse.STL" />
        <mesh name="inner_knuckle_coarse" file="inner_knuckle_coarse.STL" />
        <mesh name="inner_finger_coarse" file="inner_finger_coarse.STL" />
        <mesh name="outer_knuckle_coarse" file="outer_knuckle_coarse.STL" />
        <mesh name="outer_finger_coarse" file="outer_finger_coarse.STL" />

        <!--Textures-->
        <texture name="ur5_tex"     type="2d"       builtin="flat" height="32" width="32" rgb1="0.45 0.45 0.45" />
        <texture name="gripper_tex" type="2d"       builtin="flat" height="32" width="32" rgb1="0.45 0.45 0.45" rgb2="0 0 0"/>
        <texture name="bench_tex"   type="2d"       builtin="flat" height="32" width="32" rgb1="0.7 0.7 0.7" />
        <texture name="sky_tex"     type="skybox"   builtin="gradient" width="100" height="100" rgb1="1 1 1" rgb2="0.3 0.3 0.8" />
        <texture name="texgeom"     type="cube"     builtin="flat" mark="cross" width="127" height="1278" rgb1="0.8 0.6 0.4" rgb2="0.8 0.6 0.4" markrgb="1 1 1" random="0.01" />
        <texture name="floor_tex"   type="2d"        builtin="checker" rgb1=".2 .3 .4" rgb2=".1 .2 .3" width="100" height="100" />
        <texture name="wood"        type="cube"     file="wood2.png"/>
        <texture name="metal"        type="cube"     file="metal2.png"/>
        <!--Materials-->
        <material name="ur5_mat"        texture="ur5_tex"   shininess="0.9" specular="0.75" reflectance="0.3"/>
        <material name="gripper_mat"    texture="gripper_tex"   shininess="0.9" specular="0.75" reflectance="0.4"/>
        <material name='floor_mat'      texture="floor_tex"  shininess="0.8" texrepeat="10 10" specular="0.7"  reflectance="0.5" />
        <material name='geom'           texture="texgeom"   texuniform="true" />
        <material name="bench_mat"      texture="metal"   shininess="0.1" specular="0.5" reflectance="0.2"/>
        <material name="tablecube"      texture="wood" rgba=".8 .8 .8 1"/>
    </asset>

    <!--Contacts-->
    <contact>
        <exclude body1="box_link" body2="base_link"/>
		<exclude body1="base_link" body2="shoulder_link"/>
		<exclude body1="shoulder_link" body2="upper_arm_link"/>
        <exclude body1="upper_arm_link" body2="forearm_link"/>
		<exclude body1="forearm_link" body2="wrist_1_link"/>
		<exclude body1="wrist_1_link" body2="wrist_2_link"/>
        <exclude body1="wrist_2_link" body2="wrist_3_link"/>
        <exclude body1="ee_link" body2="wrist_3_link"/>
    </contact>


    <!--MODEL DESCRIPTION-->
    <worldbody>
        <!--Lighting parameters-->
        <light name="light3" mode="targetbody" target="box_link" directional="true" pos="1 -1 3" />
        <!-- <light name="light3" mode="targetbody" target="box_link" directional="true" pos="1 1 3" /> -->
        <!--Camera parameters-->
        <camera name="main1" mode="fixed" target="ee_link" pos="2 2 2.7" axisangle="2 2 -2 1"/>
        <camera name="top_down" mode="fixed" target="ee_link" pos="0 -0.6 2.0" axisangle="2 2 2 0"/>
        <camera name="side" mode="fixed" target="ee_link" pos="0.8 -0.6 1.0" quat="0.5 0.5 0.5 0.5"/>
        <!--Floor Property-->
        <geom name='floor' material="floor_mat" pos='0 0 0' size='2.5 2.5 0.1'  type='plane' />


        <body name="box_2_link" pos="0 -0.6 0.435">
            <!--<geom size=".3 .2 .435" type="box" material="bench_mat"/>-->
            <geom size=".29 .19 .03" pos ="0 0 0.4" type="box" material="bench_mat"/>
            <geom size=".29 .19 .03" pos ="0 0 -0.2" type="box" material="bench_mat"/>
            <geom size=".04 .04 .435" pos =".26 .16 0" type="box" material="bench_mat"/>
            <geom size=".04 .04 .435" pos ="-.26 .16 0" type="box" material="bench_mat"/>
            <geom size=".04 .04 .435" pos =".26 -.16 0" type="box" material="bench_mat"/>
            <geom size=".04 .04 .435" pos ="-.26 -.16 0" type="box" material="bench_mat"/>
            <inertial pos="0 0 0" mass="1000" diaginertia="0 0 0" />
        </body>


        <body name="drop_box" pos="0.6 0.0 0.0">
            <geom size=".2 .3 .03" pos ="0 0 0.615" type="box" material="bench_mat"/>
            <geom size=".03 .3 .4" pos ="0.23 0.0 0.4" type="box" material="bench_mat"/>
            <geom size=".03 .3 .4" pos ="-0.23 0.0 0.4" type="box" material="bench_mat"/>
            <geom size=".26 .03 .4" pos ="0.0 0.33 0.4" type="box" material="bench_mat"/>
            <geom size=".26 .03 .4" pos ="0.0 -0.33 0.4" type="box" material="bench_mat"/>
            <inertial pos="0 0 0" mass="1000" diaginertia="0 0 0" />
        </body>


        <!--Robot UR5-->
        <body name="box_link" pos="0 0 0.435">
            <!--<geom size=".3 .2 .435" type="box" material="bench_mat"/>-->
            <geom size=".29 .19 .03" pos ="0 0 0.4" type="box" material="bench_mat"/>
            <geom size=".29 .19 .03" pos ="0 0 -0.2" type="box" material="bench_mat"/>
            <geom size=".04 .04 .435" pos =".26 .16 0" type="box" material="bench_mat"/>
            <geom size=".04 .04 .435" pos ="-.26 .16 0" type="box" material="bench_mat"/>
            <geom size=".04 .04 .435" pos =".26 -.16 0" type="box" material="bench_mat"/>
            <geom size=".04 .04 .435" pos ="-.26 -.16 0" type="box" material="bench_mat"/>
            <inertial pos="0 0 0" mass="1000" diaginertia="0 0 0" />
            <body name="base_link" pos="0 0 0.435">
                <inertial pos="0 0 0" quat="0.5 0.5 -0.5 0.5" mass="4" diaginertia="0.0072 0.00443333 0.00443333" />
                <geom type="mesh"  mesh="base" material="ur5_mat"/>
                <body name="shoulder_link" pos="0 0 0.089159">
                    <inertial pos="0 0 0" mass="3.7" diaginertia="0.0102675 0.0102675 0.00666" />
                    <joint name="shoulder_pan_joint" class="UR5" pos="0 0 0" axis="0 0 1" limited="true" range="-3.14159 3.14159" />
                    <geom type="mesh"  mesh="shoulder" material="ur5_mat"/>
                    <body name="upper_arm_link" pos="0 0.13585 0" quat="0.707107 0 0.707107 0">
                        <inertial pos="0 0 0.28" mass="8.393" diaginertia="0.226891 0.226891 0.0151074" />
                        <joint name="shoulder_lift_joint" class="UR5" pos="0 0 0" axis="0 1 0" limited="true" range="-3.14159 0" /> <!--Range= -3.14159 3.14159-->
                        <geom type="mesh"  mesh="upperarm" material="ur5_mat"/>
                        <body name="forearm_link" pos="0 -0.1197 0.425">
                            <inertial pos="0 0 0.25" mass="2.275" diaginertia="0.0494433 0.0494433 0.004095" />
                            <joint name="elbow_joint" class="UR5" pos="0 0 0" axis="0 1 0" limited="true" range="-3.14159 3.14159" />
                            <geom type="mesh"  mesh="forearm" material="ur5_mat"/>
                            <body name="wrist_1_link" pos="0 0 0.39225" quat="0.707107 0 0.707107 0">
                                <inertial pos="0 0 0" quat="0.5 0.5 -0.5 0.5" mass="1.219" diaginertia="0.21942 0.111173 0.111173" />
                                <joint name="wrist_1_joint" class="UR5e" pos="0 0 0" axis="0 1 0" limited="true" range="-3.14159 3.14159" />
                                <geom type="mesh"  mesh="wrist1" material="ur5_mat"/>
                                <body name="wrist_2_link" pos="0 0.093 0">
                                    <inertial pos="0 0 0" quat="0.5 0.5 -0.5 0.5" mass="1.219" diaginertia="0.21942 0.111173 0.111173" />
                                    <joint name="wrist_2_joint" class="UR5e" pos="0 0 0" axis="0 0 1" limited="true" range="-3.14159 3.14159" />
                                    <geom type="mesh"  mesh="wrist2" material="ur5_mat"/>
                                    <body name="wrist_3_link" pos="0 0 0.09465">
                                        <inertial pos="0 0 0" quat="0.5 0.5 -0.5 0.5" mass="0.1879" diaginertia="0.033822 0.0171365 0.0171365" />
                                        <joint name="wrist_3_joint" class="UR5e" pos="0 0 0" axis="0 1 0" limited="true" range="-3.14159 3.14159" />
                                        <geom type="mesh"  mesh="wrist3" material="ur5_mat"/>
                                        <body name="ee_link" pos="0 0.0823 0" quat="0.707107 0 0 0.707107">
                                            <inertial pos="-0.01 0 0" mass="0.001" diaginertia="1.66667e-08 1.66667e-08 1.66667e-08" />
                                            <geom size="0.005 0.005 0.005" pos="-0.01 0 0" type="box" />
                                        <!--GRIPPER-->
                                             <!-- <joint name="ee_to_base" pos="0 0 0" axis="1 0 0" limited="true" range="0 0" /> -->
                                            <body name="robotiq_85_base_link" pos="0 0 0" quat="0.5 0.5 0.5 0.5 ">
                                            <inertial pos="0.00021987 -2.3546e-10 0.030163"  quat="0.707058 0.00723369 0.00723345 0.707081" mass="0.30915" diaginertia="0.00030737 0.000289758 0.000199102" />
                                            <geom type="mesh" rgba="0.1 0.1 0.1 1" friction="0.8 0.8 0.8" mesh="robotiq_85_base_link_coarse" />
                                      
                                            <body name="left_inner_knuckle" pos="0.0127 0 0.0693075">
                                                <inertial pos="0.0170975 -3.93809e-10 0.0224918"   quat="0.947655 0 -0.319297 0" mass="0.0110931" diaginertia="5.59353e-06 3.96549e-06 1.88108e-06" />
                                                <geom type="mesh" rgba="0.1 0.1 0.1 1" friction="0.8 0.8 0.8" mesh="inner_knuckle_coarse" />
                                                 <joint name="base_to_lik" class="GRIPPER" pos="0 0 0" axis="0 1 0" limited="true" range="-1 1" />

                                                <body name="left_inner_finger" pos="0.0345853 0 0.045497" >
                                                    <inertial pos="0.00602756 0 0.00669926"  quat="0.699065 0.106339 0.106339 0.699065" mass="0.00724255" diaginertia="1.70064e-06 1.58577e-06 3.69621e-07" />
                                                    <geom type="mesh" rgba="0.1 0.1 0.1 1" friction="0.8 0.8 0.8" mesh="inner_finger_coarse" />
                                                </body>
                                            </body>

                                            <body name="right_inner_knuckle" pos="-0.0127 0 0.0693075" quat="0 0 0 1">
                                                <inertial pos="0.0168606 3.93808e-10 0.02267"  quat="0.949317 0 -0.314322 0" mass="0.0110931" diaginertia="5.59353e-06 3.96549e-06 1.88108e-06" />
                                                <geom type="mesh" rgba="0.1 0.1 0.1 1" friction="0.8 0.8 0.8" mesh="inner_knuckle_coarse" />
                                                <joint name="base_to_rik" class="GRIPPER" pos="0 0 0" axis="0 1 0" limited="true" range="-1 1" />

                                                <body name="right_inner_finger" pos="0.034106 0 0.0458574">
                                                    <inertial pos="0.00602756 0 0.00669926"  quat="0.699065 0.106339 0.106339 0.699065" mass="0.00724255" diaginertia="1.70064e-06 1.58577e-06 3.69621e-07" />
                                                    <geom type="mesh" rgba="0.1 0.1 0.1 1" friction="0.8 0.8 0.8" mesh="inner_finger_coarse" />
                                                </body>
                                            </body>
                                    </body>
                                </body>
                            </body>
                        </body>
                    </body>
                </body>
            </body>
        </body>
    </body>
                <body name="base" pos="0 0 0" quat="1.7949e-09 0 0 -1">
                    <inertial pos="0 0 0" quat="1.7949e-09 0 0 -1" mass="0" diaginertia="0 0 0" />
                </body>
        </body>

   <!--      <body name="pick_box_1" pos="0 -0.6 0.9">
                <freejoint name="tablebox_joint" />
                <geom size="0.03 0.03 0.03" pos="0 0 0.03" type="box" material="tablecube"/>
                <inertial pos="0 0 0.03" mass="0.5" diaginertia="0 0 0" />
        </body> -->

        <body name="box_1" pos=".0 -.6 0.9">
            <joint armature="0" axis="1 0 0" damping="0" limited="false" name="box_1_x" pos="0 0 0" range="-5. 5." stiffness="0" type="slide"/>
            <joint armature="0" axis="0 1 0" damping="0" limited="true" name="box_1_y" pos="0 0 0" range="-5. 5." stiffness="0" type="slide"/>
            <joint armature="0" axis="0 0 1" damping="0" limited="true" name="box_1_z" pos="0 0 0" range="-2. 2." stiffness="0" type="slide"/>
            <!-- <joint armature="0" damping="0" name="box_1_rot" pos="0 0 0" stiffness="0" type="ball"/> -->
            <geom name="box_1" pos="0 0 0" material="tablecube" size="0.02 0.02 0.02" type="box"/>
            <inertial pos="0 0 0" mass="0.2" diaginertia="0.001 0.001 0.001" />
        </body>

        <body name="box_2" pos=".0 -.6 1.0">
            <joint armature="0" axis="1 0 0" damping="0" limited="true" name="box_2_x" pos="0 0 0" range="-5. 5." stiffness="0" type="slide"/>
            <joint armature="0" axis="0 1 0" damping="0" limited="true" name="box_2_y" pos="0 0 0" range="-5. 5." stiffness="0" type="slide"/>
            <joint armature="0" axis="0 0 1" damping="0" limited="true" name="box_2_z" pos="0 0 0" range="-2. 2." stiffness="0" type="slide"/>
            <!-- <joint armature="0" damping="0" name="box_2_rot" pos="0 0 0" stiffness="0" type="ball"/> -->
            <geom name="box_2" pos="0 0 0" rgba="0.0 0.5 0.8 1" size="0.02 0.02 0.02" type="box"/>
            <inertial pos="0 0 0" mass="0.2" diaginertia="0.001 0.001 0.001" />
        </body>

        <body name="box_3" pos=".0 -.6 1.1">
            <joint armature="0" axis="1 0 0" damping="0" limited="true" name="box_3_x" pos="0 0 0" range="-5. 5." stiffness="0" type="slide"/>
            <joint armature="0" axis="0 1 0" damping="0" limited="true" name="box_3_y" pos="0 0 0" range="-5. 5." stiffness="0" type="slide"/>
            <joint armature="0" axis="0 0 1" damping="0" limited="true" name="box_3_z" pos="0 0 0" range="-2. 2." stiffness="0" type="slide"/>
            <!-- <joint armature="0" damping="0" name="box_3_rot" pos="0 0 0" stiffness="0" type="ball"/> -->
            <geom name="box_3" pos="0 0 0" rgba="0.8 0.8 0.1 1" size="0.02 0.02 0.02" type="box"/>
            <inertial pos="0 0 0" mass="0.2" diaginertia="0.001 0.001 0.001" />
        </body>

        <body name="ball_1" pos=".0 -.6 1.2">
            <joint armature="0" axis="1 0 0" damping="0" limited="true" name="ball_1_x" pos="0 0 0" range="-5. 5." stiffness="0" type="slide"/>
            <joint armature="0" axis="0 1 0" damping="0" limited="true" name="ball_1_y" pos="0 0 0" range="-5. 5." stiffness="0" type="slide"/>
            <joint armature="0" axis="0 0 1" damping="0" limited="true" name="ball_1_z" pos="0 0 0" range="-2. 2." stiffness="0" type="slide"/>
            <!-- <joint armature="0" damping="0" name="ball_1_rot" pos="0 0 0" stiffness="0" type="ball"/> -->
            <geom name="ball_1" pos="0 0 0" rgba="0.9 0.2 0.2 1" size=".03" type="sphere"/>
            <inertial pos="0 0 0" mass="0.2" diaginertia="0.001 0.001 0.001" />
        </body>

        <body name="ball_2" pos=".0 -.6 1.3">
            <joint armature="0" axis="1 0 0" damping="0" limited="true" name="ball_2_x" pos="0 0 0" range="-5. 5." stiffness="0" type="slide"/>
            <joint armature="0" axis="0 1 0" damping="0" limited="true" name="ball_2_y" pos="0 0 0" range="-5. 5." stiffness="0" type="slide"/>
            <joint armature="0" axis="0 0 1" damping="0" limited="true" name="ball_2_z" pos="0 0 0" range="-2. 2." stiffness="0" type="slide"/>
            <!-- <joint armature="0" damping="0" name="ball_2_rot" pos="0 0 0" stiffness="0" type="ball"/> -->
            <geom name="ball_2" pos="0 0 0" material="geom" size=".03" type="sphere"/>
            <inertial pos="0 0 0" mass="0.2" diaginertia="0.001 0.001 0.001" />
        </body>

        <body name="ball_3" pos=".0 -.6 1.4">
            <joint armature="0" axis="1 0 0" damping="0" limited="true" name="ball_3_x" pos="0 0 0" range="-5. 5." stiffness="0" type="slide"/>
            <joint armature="0" axis="0 1 0" damping="0" limited="true" name="ball_3_y" pos="0 0 0" range="-5. 5." stiffness="0" type="slide"/>
            <joint armature="0" axis="0 0 1" damping="0" limited="true" name="ball_3_z" pos="0 0 0" range="-2. 2." stiffness="0" type="slide"/>
            <!-- <joint armature="0" damping="0" name="ball_3_rot" pos="0 0 0" stiffness="0" type="ball"/> -->
            <geom name="ball_3" pos="0 0 0" rgba="0.2 0.2 0.5 1" size=".03" type="sphere"/>
            <inertial pos="0 0 0" mass="0.2" diaginertia="0.001 0.001 0.001" />
        </body>

<!--         <body name="cylinder_1" pos=".15 -.55 1.3">
            <joint armature="0" axis="1 0 0" damping="0" limited="true" name="cylinder_1_x" pos="0 0 0" range="-5. 5." ref=".1" stiffness="0" type="slide"/>
            <joint armature="0" axis="0 1 0" damping="0" limited="true" name="cylinder_1_y" pos="0 0 0" range="-5. 5." ref="-.1" stiffness="0" type="slide"/>
            <joint armature="0" axis="0 0 1" damping="0" limited="true" name="cylinder_1_z" pos="0 0 0" range="-2. 2." ref="-.1" stiffness="0" type="slide"/>
            <geom name="cylinder_1" pos="0 0 0" material="geom" size=".025 0.05" type="cylinder"/>
            <inertial pos="0 0 0.01" mass="0.2" diaginertia="0 0 0" />
        </body>
 -->

    </worldbody>


   <!--  <tendon>
		<fixed name="middle12_cpl" range="0 1">
			<joint joint="base_to_rik"  coef="1"/>
			<joint joint="base_to_lik"  coef="-1"/>
		</fixed>
    </tendon> -->
	<!-- 	<fixed name="middle23_cpl" range="0 1">
			<joint joint="gripperfinger_middle_joint_2"  coef="1"/>
			<joint joint="gripperfinger_middle_joint_3"  coef="-3.5"/>
		</fixed>

        <fixed name="finger2_12_cpl" range="0 1">
			<joint joint="gripperfinger_2_joint_1"  coef="1"/>
			<joint joint="gripperfinger_2_joint_2"  coef="-1.5"/>
		</fixed>
		<fixed name="finger2_23_cpl" range="0 1">
			<joint joint="gripperfinger_2_joint_2"  coef="1"/>
			<joint joint="gripperfinger_2_joint_3"  coef="-3.5"/>
		</fixed>

        <fixed name="finger1_12_cpl" range="0 1">
			<joint joint="gripperfinger_1_joint_1"  coef="1"/>
			<joint joint="gripperfinger_1_joint_2"  coef="-1.5"/>
		</fixed>
		<fixed name="finger1_23_cpl" range="0 1">
			<joint joint="gripperfinger_1_joint_2"  coef="1"/>
			<joint joint="gripperfinger_1_joint_3"  coef="-3.5"/>
		</fixed>
	</tendon> -->

    <equality>
		<!-- <tendon name="middle12_cpl" 	tendon1="middle12_cpl"/> -->
		<!-- <tendon name="middle23_cpl" 	tendon1="middle23_cpl"/> -->

        <!-- <tendon name="finger2_12_cpl" 	tendon1="finger2_12_cpl"/> -->
		<!-- <tendon name="finger2_23_cpl" 	tendon1="finger2_23_cpl"/> -->

        <!-- <tendon name="finger1_12_cpl" 	tendon1="finger1_12_cpl"/> -->
		<!-- <tendon name="finger1_23_cpl" 	tendon1="finger1_23_cpl"/> -->

		<joint name="fingers" joint1="base_to_rik" joint2="base_to_lik" polycoef="0 1 0 0 0"/>
	</equality>


    <!--ACTUATORS-->
    <actuator>
        <!--UR5-->
        <!--<position name='shoulder_pan' ctrllimited="true" ctrlrange="-3.14159 3.14159" joint='shoulder_pan_joint' kp="500"/>-->
        <!--<position name='shoulder_lift' ctrllimited="true" ctrlrange="-3.14159 3.14159" joint='shoulder_lift_joint' kp="500"/>-->
        <!--<position name='forearm' ctrllimited="true" ctrlrange="-3.14159 3.14159" joint='elbow_joint' kp="500"/>-->
        <!--<position name='wrist_1' ctrllimited="true" ctrlrange="-3.14159 3.14159" joint='wrist_1_joint' kp="100"/>-->
        <!--<position name='wrist_2' ctrllimited="true" ctrlrange="-3.14159 3.14159" joint='wrist_2_joint' kp="100"/>-->
        <!--<position name='wrist_3' ctrllimited="true" ctrlrange="-3.14159 3.14159" joint='wrist_3_joint' kp="100"/>-->

        <motor name='shoulder_pan_T' ctrllimited="true" ctrlrange="-2 2" joint='shoulder_pan_joint' gear="101"/> <!--range -150 150-->
        <motor name='shoulder_lift_T' ctrllimited="true" ctrlrange="-2 2" joint='shoulder_lift_joint' gear="101"/>
        <motor name='forearm_T' ctrllimited="true" ctrlrange="-2 2" joint='elbow_joint' gear="101" />
        <motor name='wrist_1_T' ctrllimited="true" ctrlrange="-1 1" joint='wrist_1_joint' gear="101"/>  <!--range -28 28-->
        <motor name='wrist_2_T' ctrllimited="true" ctrlrange="-1 1" joint='wrist_2_joint' gear="101"/>
        <motor name='wrist_3_T' ctrllimited="true" ctrlrange="-1 1" joint='wrist_3_joint' gear="101"/>




        <motor name='gripper_motor' ctrllimited="true" ctrlrange="-1 1" joint='base_to_lik' gear="101"/>

        <!--<velocity name='shoulder_pan_v' class="UR5" joint='shoulder_pan_joint' kv="10"/>-->
        <!--<velocity name='shoulder_lift_v' class="UR5" joint='shoulder_lift_joint' />-->
        <!--<velocity name='forearm_v' class="UR5" joint='elbow_joint' />-->
        <!--<velocity name='wrist_1_v' class="UR5" joint='wrist_1_joint' />-->
        <!--<velocity name='wrist_2_v' class="UR5" joint='wrist_2_joint'/>-->
        <!--<velocity name='wrist_3_v' class="UR5" joint='wrist_3_joint'/>-->

        <!--Gripper-->
        <!--<position name='finger_1' ctrllimited="true" kp="20" joint='gripperfinger_1_joint_1' ctrlrange='0 1.2217'/>-->
        <!--<position name='finger_2' ctrllimited="true" kp="20" joint='gripperfinger_2_joint_1' ctrlrange='0 1.2217'/>-->
        <!--<position name='middle_finger'  ctrllimited="true" kp="20" joint='gripperfinger_middle_joint_1' ctrlrange='0 1.2217'/>-->
        <!--<position name='finger_scissor' ctrllimited="true" kp="20" joint='gripperpalm_finger_1_joint' ctrlrange="-0.2967 0.2967"/>-->

        <!-- <motor name='finger_1_T' ctrllimited="true" joint='gripperfinger_1_joint_1' ctrlrange='-0.5 .8' gear="20"/> -->
        <!-- <motor name='finger_2_T' ctrllimited="true" joint='gripperfinger_2_joint_1' ctrlrange='-0.5 .8' gear="20"/> -->
        <!-- <motor name='middle_finger_T'  ctrllimited="true" joint='gripperfinger_middle_joint_1' ctrlrange='-0.5 .8' gear="20"/> -->
        <!-- <motor name='finger_scissor_T' ctrllimited="true" joint='gripperpalm_finger_1_joint' ctrlrange="-0.8 0.8" gear="15"/>    -->

     <!--    
        <motor name='finger_1_T' ctrllimited="true" joint='gripperfinger_1_joint_1' ctrlrange='-0.1 .8' gear="20"/>
        <motor name='finger_2_T' ctrllimited="true" joint='gripperfinger_2_joint_1' ctrlrange='-0.1 .8' gear="20"/>
        <motor name='middle_finger_T'  ctrllimited="true" joint='gripperfinger_middle_joint_1' ctrlrange='-0.1 .8' gear="20"/>
        <motor name='finger_scissor_T' ctrllimited="true" joint='gripperpalm_finger_1_joint' ctrlrange="-0.8 0.8" gear="15"/> -->
    </actuator>

   <!--  <sensor>
        <touch name="gripperpalm_frc" 		site="gripperpalm"/>

        <touch name="finger_1_polp_1_frc"	site="gripperfinger_1_polp_1"/>
    	<touch name="finger_1_polp_2_frc" 	site="gripperfinger_1_polp_2"/>
        <touch name="finger_1_polp_3_frc" 	site="gripperfinger_1_polp_3"/>

        <touch name="finger_2_link_1_frc" 	site="gripperfinger_2_polp_1"/>
        <touch name="finger_2_link_2_frc" 	site="gripperfinger_2_polp_2"/>
        <touch name="finger_2_link_3_frc" 	site="gripperfinger_2_polp_3"/>

        <touch name="finger_middle_link_1_frc" 	site="gripperfinger_middle_polp_1"/>
        <touch name="finger_middle_link_2_frc" 	site="gripperfinger_middle_polp_2"/>
        <touch name="finger_middle_link_3_frc" 	site="gripperfinger_middle_polp_3"/>
    </sensor> -->
</mujoco>
